Workbook

Sheet Original Data
A1: Empresa | B1: BLOOOMBERG TICKER | C1: ISiN Code | D1: Indicadores
D2: Moeda | E2: Preço Ação Primeira Abertura | F2: Preço Ação Último Fechamento | G2: Market Cap em bi | H2: Volume Médio em mi | I2: Índice P/L | J2: Rend. Dividendos | K2: ROI 5YA | L2: ROA 5YA | M2: ROE 5YA | N2: Lucro por Ação | P2: Receita Total em bi | S2: EBITDA em bi | W2: Pontuação CDP | AC2: ESG Ratings | AG2: Controversy Level
O3: 2018 | P3: 2019 | Q3: 2020 | R3: 2021 | S3: 2018 | T3: 2019 | U3: 2020 | V3: 2021 | W3: Climate Change 2020 | X3: Climate Change 2021 | Y3: Forests 2020 | Z3: Forests 2021 | AA3: Water Security 2020 | AB3: Water Security 2021 | AC3: Total ESG Risk Score | AD3: Environment Risk Score | AE3: Social Risk Score | AF3: Governance Risk Score
A4: BMW AG | B4: BMW GY Equity | C4: DE0005190003 | D4: Euro | E4: 14.1 | F4: 76.67 | G4: 49.57 | H4: 2.44 | I4: 4.22 | J4: 0.0766 | K4: 0.0541 | L4: 0.035 | M4: 0.1255 | N4: 18.77 | O4: 96.86 | P4: 104.21 | Q4: 98.99 | R4: 111.24 | S4: 17.4 | T4: 17.98 | U4: 11 | V4: 19.94 | W4: A | X4: A- | Y4: Declined to participate | Z4: Declined to participate | AA4: Declined to participate | AB4: Declined to participate | AC4: 24 | AD4: 7.2 | AE4: 7.5 | AF4: 9.2 | AG4: 3
A5: WALT DISNEY CO | B5: DIS US Equity | C5: US2546871060 | D5: Dolar | E5: 1.19 | F5: 138.62 | G5: 255.09 | H5: 12.41 | I5: 83.15 | J5: - | K5: 0.0554 | L5: 0.043 | M5: 0.0897 | N5: 1.11 | O5: 59.47 | P5: 69.42 | Q5: 65.13 | R5: 67.39 | S5: 17.93 | T5: 15.88 | U5: 8.92 | V5: 8.85 | W5: B- | X5: B | Y5: Not Scored | Z5: Not Scored | AA5: - | AB5: - | AC5: 14 | AD5: 0.1 | AE5: 7.1 | AF5: 7.2 | AG5: 2
A6: ACCENTURE PLC-A | B6: ACN US Equity | C6: IE00B4BNMY34 | D6: Dolar | E6: 18.31 | F6: 324.56 | G6: 214.96 | H6: 2.86 | I6: 33 | J6: 0.0118 | K6: 0.2756 | L6: 0.1648 | M6: 0.3653 | N6: 9.92 | O6: 40.99 | P6: 43.22 | Q6: 44.33 | R6: 50.53 | S6: 6.92 | T6: 7.25 | U6: 8.34 | V6: 9.62 | W6: A | X6: A- | Y6: - | Z6: - | AA6: - | AB6: - | AC6: 9 | AD6: 0.3 | AE6: 4.3 | AF6: 4.8 | AG6: 2
A7: MCDONALDS CORP | B7: MCD US Equity | C7: US5801351017 | D7: Dolar | E7: 0.81 | F7: 235.32 | G7: 177.06 | H7: 4.02 | I7: 23.73 | J7: 0.0232 | K7: 0.1595 | L7: 0.1447 | M7: -% | N7: 10.04 | O7: 21.03 | P7: 21.36 | Q7: 19.21 | R7: 23.22 | S7: 10.07 | T7: 10.5 | U7: 8.91 | V7: 11.64 | W7: C | X7: C | Y7: D/C | Z7: B-/B | AA7: C | AB7: D | AC7: 24 | AD7: 4.1 | AE7: 14.4 | AF7: 5.9 | AG7: 3
A8: HYUNDAI MOTO-GDR | B8: HYUD LI Equity | C8: USY384721251 | D8: Dolar | E8: 3.2 | F8: 34.1 | G8: 32.31 | H8: 0.007846 | I8: - | J8: 0.0521 | K8: 0.025 | L8: 0.0175 | M8: 0.0428 | N8: 18991.81 | O8: 96810 | P8: 105750 | Q8: 104000 | R8: 117611 | S8: 6180 | T8: 7620 | U8: 6780 | V8: 11440 | W8: A- | X8: B | Y8: No Response | Z8: No Response | AA8: A- | AB8: A- | AC8: - | AD8: - | AE8: - | AF8: - | AG8: -
A9: CATERPILLAR INC | B9: CAT US Equity | C9: US1491231015 | D9: Dolar | E9: 6.03 | F9: 223.67 | G9: 119.88 | H9: 4.2 | I9: 18.93 | J9: 0.0199 | K9: 0.0954 | L9: 0.0623 | M9: 0.3375 | N9: 11.86 | O9: 54.72 | P9: 53.79 | Q9: 41.75 | R9: 50.98 | S9: 11.43 | T9: 11.07 | U9: 7.41 | V9: 9.32 | W9: No Response | X9: No Response | Y9: - | Z9: - | AA9: No Response | AB9: No Response | AC9: 34 | AD9: 7.2 | AE9: 18.5 | AF9: 8.6 | AG9: 4
A10: ALIBABA GRP-ADR | B10: BABA US Equity | C10: US01609W1027 | D10: Dolar | E10: 85.88 | F10: 103.53 | G10: 281.83 | H10: 35.92 | I10: 30.63 | J10: -% | K10: 0.153 | L10: 0.1083 | M10: 0.2004 | N10: 8.75 | O10: 250.266 | P10: 376.844 | Q10: 509.711 | R10: 717.289 | S10: 108.99 | T10: 121.943 | U10: 157.659 | V10: 196.842 | W10: No Response | X10: No Response | Y10: No Response | Z10: No Response | AA10: - | AB10: - | AC10: - | AD10: - | AE10: - | AF10: - | AG10: -
A11: STARBUCKS CORP | B11: SBUX US Equity | C11: US8552441094 | D11: Dolar | E11: 0.32 | F11: 86.86 | G11: 99.92 | H11: 10.13 | I11: 23.71 | J11: 0.0223 | K11: 0.2031 | L11: 0.1481 | M11: -% | N11: 3.57 | O11: 24.72 | P11: 26.5 | Q11: 23.51 | R11: 29.06 | S11: 5.17 | T11: 5.35 | U11: 4.22 | V11: 7.44 | W11: D | X11: B | Y11: D/C | Z11: D/B- | AA11: B- | AB11: B | AC11: 25 | AD11: 6.1 | AE11: 14.2 | AF11: 4.3 | AG11: 2
A12: VIDRALA | B12: VID SM Equity | C12: ES0183746314 | D12: Euro | E12: 4.6 | F12: 64.8 | G12: 1.93 | H12: 0.03867 | I12: 13.52 | J12: 0.0176 | K12: 0.1195 | L12: 0.0908 | M12: 0.1921 | N12: 4.88 | O12: 0.95543 | P12: 1.01 | Q12: 0.98892 | R12: 1.08 | S12: 0.21737 | T12: 0.25832 | U12: 0.25789 | V12: 0.23076 | W12: No Response | X12: B | Y12: - | Z12: - | AA12: No Response | AB12: B | AC12: - | AD12: - | AE12: - | AF12: - | AG12: -
A13: ROYAL DUTCH SH-A | B13: RDSA NA Equity | C13: GB00B03MLX29 | D13: Euro | E13: 26.44 | F13: 24.14 | G13: 189.846 | H13: 15.264 | I13: 10.72 | J13: 0.0321 | K13: 0.0246 | L13: 0.0197 | M13: 0.0401 | N13: 2.33 | O13: 388.379 | P13: 344.877 | Q13: 180.543 | R13: 261.504 | S13: 36.758 | T13: 21.447 | U13: 10.758 | V13: 31.734 | W13: B | X13: B | Y13: No Response | Z13: No Response | AA13: No Response | AB13: No Response | AC13: 35 | AD13: 19.4 | AE13: 8.2 | AF13: 7.9 | AG13: 4
A14: HOLCIM LTD | B14: HOLN SW Equity | C14: CH0012214059 | D14: Franco Suíço | E14: 29.91 | F14: 46.18 | G14: 28.44 | H14: 2.5 | I14: 12.31 | J14: -% | K14: 0.0308 | L14: 0.024 | M14: 0.0434 | N14: 3.73 | O14: 27.47 | P14: 26.72 | Q14: 23.14 | R14: 26.83 | S14: 5.5 | T14: 6.2 | U14: 5.48 | V14: 6.42 | W14: A | X14: A | Y14: - | Z14: - | AA14: A- | AB14: A- | AC14: 21 | AD14: 11.9 | AE14: 3 | AF14: 6.3 | AG14: 3
A15: MICHELIN | B15: ML FP Equity | C15: FR0000121261 | D15: Euro | E15: 31.34 | F15: 123.25 | G15: 21.97 | H15: 0.058393 | I15: 12.4 | J15: 0.0365 | K15: 0.0664 | L15: 0.0508 | M15: 0.1219 | N15: 10.31 | O15: 22.03 | P15: 24.14 | Q15: 20.47 | R15: 23.8 | S15: 4.12 | T15: 4.76 | U15: 3.73 | V15: - | W15: A- | X15: A | Y15: No Responde | Z15: Not Scored | AA15: A- | AB15: B | AC15: 13 | AD15: 3 | AE15: 4.2 | AF15: 5.4 | AG15: 2
A16: RYANAIR HLDGS | B16: RYA ID Equity | C16: IE00BYTBXV33 | D16: Euro | E16: 1.97 | F16: 13.7 | G16: 15.51 | H16: 2.67 | I16: - | J16: -% | K16: 0.0737 | L16: 0.0512 | M16: 0.1419 | N16: -0.91 | O16: 7.15 | P16: 7.7 | Q16: 8.49 | R16: 1.64 | S16: 2.23 | T16: 1.66 | U16: 1.88 | V16: - | W16: B- | X16: B | Y16: - | Z16: - | AA16: - | AB16: - | AC16: 30 | AD16: 8.8 | AE16: 15.3 | AF16: 5.4 | AG16: 3
A17: TRIGANO SA | B17: TRI FP Equity | C17: FR0005691656 | D17: Euro | E17: 2.9 | F17: 139.7 | G17: 2.73 | H17: 31.07 | I17: 12.08 | J17: 0.0308 | K17: 0.1656 | L17: 0.1101 | M17: 0.207 | N17: 11.55 | O17: 2.31 | P17: 2.33 | Q17: 2.18 | R17: 2.93 | S17: 0.25342 | T17: 0.23584 | U17: 0.23776 | V17: 0.42454 | W17: No Response | X17: No Response | Y17: - | Z17: - | AA17: - | AB17: - | AC17: - | AD17: - | AE17: - | AF17: - | AG17: -
A18: BENETEAU | B18: BEN FP Equity | C18: FR0000035164 | D18: Euro | E18: 0.18 | F18: 14.16 | G18: 1.2 | H18: 0.101 | I18: - | J18: -% | K18: -% | L18: -% | M18: -% | N18: - | O18: 1.29 | P18: 1.34 | Q18: 1.01 | R18: 1.23 | S18: 0.1536 | T18: 0.15511 | U18: 0.07146 | V18: - | W18: No Response | X18: No Response | Y18: - | Z18: - | AA18: - | AB18: - | AC18: - | AD18: - | AE18: - | AF18: - | AG18: -
A19: SAINT GOBAIN | B19: SGO FP Equity | C19: FR0000125007 | D19: Euro | E19: 36.13 | F19: 57.88 | G19: 29.72 | H19: 1.46 | I19: 12.17 | J19: 0.0287 | K19: 0.0391 | L19: 0.0279 | M19: 0.0683 | N19: 4.79 | O19: 41.77 | P19: 42.57 | Q19: 38.13 | R19: 44.16 | S19: 5.08 | T19: 5.27 | U19: 4.74 | V19: 6.44 | W19: A- | X19: A | Y19: No Response | Z19: No Response | AA19: B | AB19: A- | AC19: 20 | AD19: 8.4 | AE19: 6.1 | AF19: 5.6 | AG19: 3
A20: BEKAERT NV | B20: BEKB BB Equity | C20: BE0974258874 | D20: Euro | E20: 18.17 | F20: 36.92 | G20: 2.23 | H20: 0.09913 | I20: 5.2 | J20: 0.0286 | K20: 0.0446 | L20: 0.0276 | M20: 0.1079 | N20: 7.14 | O20: 4.31 | P20: 4.32 | Q20: 3.77 | R20: 4.84 | S20: 0.32685 | T20: 0.44446 | U20: 0.46045 | V20: 0.6433 | W20: D | X20: D | Y20: - | Z20: - | AA20: - | AB20: - | AC20: - | AD20: - | AE20: - | AF20: - | AG20: -
A21: STABILUS SA | B21: STM GY Equity | C21: LU1066226637 | D21: Euro | E21: 23.35 | F21: 50.35 | G21: 1.24 | H21: 0.03112 | I21: 15.92 | J21: 0.0253 | K21: 0.0845 | L21: 0.0701 | M21: 0.1698 | N21: 2.97 | O21: 0.96256 | P21: 0.995134 | Q21: 0.92213 | R21: 0.93767 | S21: 0.18711 | T21: 0.17702 | U21: 0.14744 | V21: 0.018202 | W21: - | X21: - | Y21: - | Z21: - | AA21: - | AB21: - | AC21: - | AD21: - | AE21: - | AF21: - | AG21: -
A22: DECEUNINCK NV | B22: DECB BB Equity | C22: BE0003789063 | D22: Euro | E22: 7.01 | F22: 2.83 | G22: 0.381 | H22: 0.22757 | I22: 11.16 | J22: -% | K22: 0.039 | L22: 0.0261 | M22: 0.0568 | N22: 0.25 | O22: 0.67423 | P22: 0.63381 | Q22: 0.64219 | R22: 0.8381 | S22: 0.06996 | T22: 0.04619 | U22: 0.08 | V22: 0.08511 | W22: No Response | X22: D | Y22: - | Z22: - | AA22: - | AB22: - | AC22: - | AD22: - | AE22: - | AF22: - | AG22: -
A23: MUENCHENER RUE-R | B23: MUV2 GY Equity | C23: DE0008430026 | D23: Euro | E23: 216.89 | F23: 240 | G23: 33.65 | H23: 0.498115 | I23: 11.47 | J23: 0.0458 | K23: -% | L23: 0.0065 | M23: 0.0695 | N23: 20.94 | O23: 57.34 | P23: 64.85 | Q23: 66.44 | R23: 70.24 | S23: - | T23: - | U23: - | V23: - | W23: B | X23: A- | Y23: - | Z23: - | AA23: - | AB23: - | AC23: 18 | AD23: 0.4 | AE23: 9.7 | AF23: 8.2 | AG23: 2
A24: AENA SME SA | B24: AENA SM Equity | C24: ES0105046009 | D24: Euro | E24: 74 | F24: 145.15 | G24: 21.86 | H24: 0.24999 | I24: - | J24: -% | K24: 0.0551 | L24: 0.0488 | M24: 0.1281 | N24: -0.4 | O24: 4.2 | P24: 4.44 | Q24: 2.18 | R24: 2.32 | S24: 2.62 | T24: 2.75 | U24: 0.85121 | V24: 0.8224 | W24: A | X24: B | Y24: - | Z24: - | AA24: - | AB24: - | AC24: 11 | AD24: 2.3 | AE24: 4.1 | AF24: 4.8 | AG24: 0
A25: CORTICEIRA AMORI | B25: COR PL Equity | C25: PTCOR0AE0006 | D25: Euro | E25: 9.35 | F25: 10.1 | G25: 1.32 | H25: 0.10593 | I25: 17.88 | J25: -% | K25: 0.1434 | L25: 0.0938 | M25: 0.1734 | N25: 0.48 | O25: 0.76312 | P25: 0.78106 | Q25: 0.74011 | R25: 0.83782 | S25: 0.12629 | T25: 0.1182 | U25: 0.10929 | V25: - | W25: Declined to participate | X25: Not Available | Y25: No Response | Z25: No Response | AA25: Declined to participate | AB25: Declined to participate | AC25: - | AD25: - | AE25: - | AF25: - | AG25: -
A26: SANOFI | B26: SAN FP Equity | C26: FR0000120578 | D26: Euro | E26: 7.19 | F26: 94.04 | G26: 119.47 | H26: 3.01 | I26: 19.08 | J26: 0.0353 | K26: 0.0623 | L26: 0.0519 | M26: 0.0975 | N26: 4.97 | O26: 34.46 | P26: 36.13 | Q26: 36.04 | R26: 37.76 | S26: 8.55 | T26: 9.82 | U26: 10.54 | V26: 11.8 | W26: A- | X26: A | Y26: No Response | Z26: No Response | AA26: A | AB26: A | AC26: 23 | AD26: 1.6 | AE26: 13.4 | AF26: 7.9 | AG26: 4
A27: KONINKLIJKE PHIL | B27: PHIA NA Equity | C27: NL0000009538 | D27: Euro | E27: 1.88 | F27: 28.28 | G27: 24.091 | H27: 3.85 | I27: 7.58 | J27: 0.0304 | K27: 0.0501 | L27: 0.0359 | M27: 0.0757 | N27: 0.67 | O27: 18.12 | P27: 19.48 | Q27: 17.31 | R27: 17.16 | S27: 3.08 | T27: 3.43 | U27: 2.87 | V27: 1.85 | W27: A | X27: A | Y27: - | Z27: - | AA27: A- | AB27: A- | AC27: 23 | AD27: 0.9 | AE27: 14.1 | AF27: 8.5 | AG27: 4
A28: ABRDN PLC | B28: ABDN LN Equity | C28: GB00BF8Q6K64 | D28: Libra Esterlina | E28: 367.36 | F28: 207 | G28: 4.46 | H28: 6.64 | I28: 4.45 | J28: 0.0718 | K28: 0.0051 | L28: 0.0049 | M28: 0.0456 | N28: 0.47 | O28: 2.17 | P28: 2.45 | Q28: 1.64 | R28: 1.8 | S28: - | T28: - | U28: - | V28: - | W28: B | X28: C | Y28: - | Z28: - | AA28: - | AB28: - | AC28: 17 | AD28: 1.4 | AE28: 8.9 | AF28: 6.9 | AG28: 2
A29: ROCHE HLDG-GENUS | B29: ROG SW Equity | C29: CH0012032048 | D29: Franco Suíço | E29: 77.36 | F29: 366.7 | G29: 319.066 | H29: 0.358 | I29: 22.74 | J29: 0.0254 | K29: 0.2377 | L29: 0.1562 | M29: 0.4135 | N29: 16.39 | O29: 56.85 | P29: 61.47 | Q29: 58.32 | R29: 62.8 | S29: 20.31 | T29: 23.21 | U29: 22.29 | V29: 21.73 | W29: Declined to participate | X29: Declined to participate | Y29: Declined to participate | Z29: Declined to participate | AA29: Declined to participate | AB29: Declined to participate | AC29: 21 | AD29: 0.9 | AE29: 12.5 | AF29: 7.7 | AG29: 2
A30: ACERINOX | B30: ACX SM Equity | C30: ES0132105018 | D30: Euro | E30: 9.35 | F30: 10.72 | G30: 2.73 | H30: 1.5 | I30: 4.86 | J30: 0.0483 | K30: 0.0605 | L30: 0.0427 | M30: 0.1085 | N30: 2.11 | O30: 5.01 | P30: 4.75 | Q30: 4.67 | R30: 6.71 | S30: 0.47354 | T30: 0.37438 | U30: 0.39784 | V30: 0.98581 | W30: B | X30: B | Y30: - | Z30: - | AA30: No Response | AB30: Not Available | AC30: - | AD30: - | AE30: - | AF30: - | AG30: -
A31: VOPAK | B31: VPK NA Equity | C31: NL0009432491 | D31: Euro | E31: 11.8 | F31: 28.05 | G31: 3.55 | H31: 0.394 | I31: 16.65 | J31: 0.0442 | K31: 0.0684 | L31: 0.0582 | M31: 0.1124 | N31: 1.71 | O31: 1.25 | P31: 1.25 | Q31: 1.19 | R31: 1.23 | S31: 0.6393 | T31: 0.7025 | U31: 0.6535 | V31: 0.67 | W31: No Response | X31: C | Y31: - | Z31: - | AA31: No Response | AB31: C | AC31: 23 | AD31: 10.6 | AE31: 8.7 | AF31: 3.8 | AG31: 1
A32: CBRE GROUP INC-A | B32: CBRE US Equity | C32: US12504L1098 | D32: Dolar | E32: 6.31 | F32: 90.27 | G32: 30.43 | H32: 1.64 | I32: 16.93 | J32: -% | K32: 0.1315 | L32: 0.0767 | M32: 0.2057 | N32: 5.48 | O32: 21.34 | P32: 23.89 | Q32: 23.83 | R32: 27.75 | S32: - | T32: - | U32: - | V32: - | W32: B- | X32: B | Y32: - | Z32: - | AA32: - | AB32: - | AC32: 7 | AD32: 1.3 | AE32: 2.5 | AF32: 3.2 | AG32: 1
A33: MEDTRONIC PLC | B33: MDT US Equity | C33: IE00BTN1Y115 | D33: Dolar | E33: 0.47 | F33: 108.97 | G33: 144.46 | H33: 6.76 | I33: 29.67 | J33: 0.0232 | K33: 0.0536 | L33: 0.0477 | M33: 0.0879 | N33: 2.6 | O33: 29.95 | P33: 30.56 | Q33: 28.91 | R33: 30.12 | S33: 9.29 | T33: 9.76 | U33: 8.28 | V33: 8.24 | W33: B | X33: B | Y33: - | Z33: - | AA33: B- | AB33: B- | AC33: 23 | AD33: 2.3 | AE33: 13.4 | AF33: 7.7 | AG33: 3
A34: ANHEUSER-BUSCH I | B34: ABI BB Equity | C34: BE0974293251 | D34: Euro | E34: 23.21 | F34: 54.44 | G34: 108.44 | H34: 2.1 | I34: 26 | J34: 0.0092 | K34: 0.0317 | L34: 0.0258 | M34: 0.0697 | N34: 2.11 | O34: 54.619 | P34: 52.329 | Q34: 46.881 | R34: 54.304 | S34: 22.08 | T34: 21.078 | U34: 17.321 | V34: 19.209 | W34: A | X34: A- | Y34: - | Z34: - | AA34: A | AB34: A | AC34: 21 | AD34: 5.9 | AE34: 7.7 | AF34: 7.5 | AG34: 3
A35: FANUC CORP | B35: 6954 JP Equity | C35: JP3802400006 | D35: Iene | E35: 10700 | F35: 21340 | G35: 4216 | H35: 0.000812 | I35: 26.78 | J35: 0.0236 | K35: 0.0871 | L35: 0.0795 | M35: 0.0902 | N35: 490.1 | O35: 726.6 | P35: 635.57 | Q35: 508.25 | R35: 551.29 | S35: 263.79 | T35: 203.01 | U35: 134.26 | V35: 157.62 | W35: B | X35: B | Y35: - | Z35: - | AA35: B | AB35: B | AC35: 26 | AD35: 7.4 | AE35: 10.6 | AF35: 7.9 | AG35: 1
A36: EURONAV NV | B36: EURN BB Equity | C36: BE0003816338 | D36: Euro | E36: 19.1 | F36: 9.9 | G36: 1.99 | H36: 0.6596 | I36: - | J36: 0.0107 | K36: 0.0081 | L36: 0.0076 | M36: 0.0129 | N36: -1.53 | O36: 0.6 | P36: 0.932 | Q36: 1.231 | R36: 0.42 | S36: 0.18 | T36: 0.515 | U36: 0.831 | V36: 0.0484 | W36: B | X36: B | Y36: - | Z36: - | AA36: - | AB36: - | AC36: - | AD36: - | AE36: - | AF36: - | AG36: -
A37: ORANGE | B37: ORA FP Equity | C37: FR0000133308 | D37: Euro | E37: 167.5 | F37: 10.69 | G37: 28.34 | H37: 9.43 | I37: 3554 | J37: 0.0658 | K37: 0.0375 | L37: 0.026 | M37: 0.066 | N37: - | O37: 41.38 | P37: 42.24 | Q37: 42.27 | R37: 42.52 | S37: 11.59 | T37: 13.6 | U37: 13.64 | V37: 12.31 | W37: B | X37: A- | Y37: - | Z37: - | AA37: - | AB37: - | AC37: 18 | AD37: 1.7 | AE37: 8.7 | AF37: 7.3 | AG37: 3
A38: LAM RESEARCH | B38: LRCX US Equity | C38: US5128071082 | D38: Dolar | E38: 2.33 | F38: 546.76 | G38: 75.73 | H38: 1.49 | I38: 16.92 | J38: 0.011 | K38: 0.2572 | L38: 0.1996 | M38: 0.4472 | N38: 27.22 | O38: 11.09 | P38: 9.64 | Q38: 10.04 | R38: 14.63 | S38: 3.55 | T38: 2.77 | U38: 2.94 | V38: 4.78 | W38: B | X38: B | Y38: - | Z38: - | AA38: B | AB38: B | AC38: 15 | AD38: 5.1 | AE38: 4.5 | AF38: 5.3 | AG38: 1
A39: GENERALI ASSIC | B39: G IM Equity | C39: IT0000062072 | D39: Euro | E39: 13.56 | F39: 18.82 | G39: 29.73 | H39: 6.09 | I39: 10.61 | J39: 0.0785 | K39: -% | L39: 0.0047 | M39: 0.0842 | N39: 1.81 | O39: 78.07 | P39: 81.91 | Q39: 78.93 | R39: 97.2 | S39: - | T39: - | U39: - | V39: - | W39: A- | X39: B | Y39: - | Z39: - | AA39: - | AB39: - | AC39: 16 | AD39: 1 | AE39: 4 | AF39: 10.8 | AG39: 2
A40: DEUTSCHE BOERSE | B40: DB1 GY Equity | C40: DE0005810055 | D40: Euro | E40: 31.8 | F40: 163.65 | G40: 29.23 | H40: 0.5657 | I40: 24.19 | J40: 0.0196 | K40: 0.0663 | L40: 0.0066 | M40: 0.1821 | N40: 6.59 | O40: 3.36 | P40: 3.52 | Q40: 4 | R40: 4.63 | S40: 1.679 | T40: 1.813 | U40: 2.025 | V40: 2.043 | W40: B | X40: B | Y40: - | Z40: - | AA40: - | AB40: - | AC40: 14 | AD40: 1.7 | AE40: 4.5 | AF40: 7.8 | AG40: 2
...

Sheet Data Converted to EUR
A1: Empresa | B1: BLOOOMBERG TICKER | C1: ISiN Code | D1: Indicadores
D2: Moeda Antiga | E2: Preço Ação Primeira Abertura | F2: Preço Ação Último Fechamento | G2: Market Cap em bi | H2: Volume Médio em mi | I2: Índice P/L | J2: Rend. Dividendos | K2: ROI 5YA | L2: ROA 5YA | M2: ROE 5YA | N2: Lucro por Ação | O2: Receita Total em bi | S2: EBITDA em bi | W2: Pontuação CDP | AC2: ESG Ratings | AG2: Controversy Level
O3: 2018 | P3: 2019 | Q3: 2020 | R3: 2021 | S3: 2018 | T3: 2019 | U3: 2020 | V3: 2021 | W3: Climate Change 2020 | X3: Climate Change 2021 | Y3: Forests 2020 | Z3: Forests 2021 | AA3: Water Security 2020 | AB3: Water Security 2021 | AC3: Total ESG Risk Score | AD3: Environment Risk Score | AE3: Social Risk Score | AF3: Governance Risk Score
A4: BMW AG | B4: BMW GY Equity | C4: DE0005190003 | D4: Euro | E4: =IFERROR(__xludf.DUMMYFUNCTION("IF($D4=""Euro"",'Original Data'!E4, IF($D4=""Dolar"",'Original Data'!E4*GOOGLEFINANCE(""Currency:USDEUR""), IF($D4=""Franco Suíço"",'Original Data'!E4*GOOGLEFINANCE(""Currency:CHFEUR""), IF($D4=""Libra Esterlina"", 'Original Data'!E4*GOOGLEFINANCE(""Curre"&"ncy:GBPEUR""), IF($D4=""Iene"",'Original Data'!E4*GOOGLEFINANCE(""Currency:JPYEUR""), IF($D4=""HKD"",'Original Data'!E4*GOOGLEFINANCE(""Currency:HKDEUR""), IF($D4=""KRW"",'Original Data'!E4*GOOGLEFINANCE(""Currency:KRWEUR""),"""")))))))"),14.1) -> 14.1 | F4: =IFERROR(__xludf.DUMMYFUNCTION("IF($D4=""Euro"",'Original Data'!F4, IF($D4=""Dolar"",'Original Data'!F4*GOOGLEFINANCE(""Currency:USDEUR""), IF($D4=""Franco Suíço"",'Original Data'!F4*GOOGLEFINANCE(""Currency:CHFEUR""), IF($D4=""Libra Esterlina"", 'Original Data'!F4*GOOGLEFINANCE(""Curre"&"ncy:GBPEUR""), IF($D4=""Iene"",'Original Data'!F4*GOOGLEFINANCE(""Currency:JPYEUR""), IF($D4=""HKD"",'Original Data'!F4*GOOGLEFINANCE(""Currency:HKDEUR""), IF($D4=""KRW"",'Original Data'!F4*GOOGLEFINANCE(""Currency:KRWEUR""),"""")))))))"),76.67) -> 76.67 | G4: =IFERROR(__xludf.DUMMYFUNCTION("IF($D4=""Euro"",'Original Data'!G4, IF($D4=""Dolar"",'Original Data'!G4*GOOGLEFINANCE(""Currency:USDEUR""), IF($D4=""Franco Suíço"",'Original Data'!G4*GOOGLEFINANCE(""Currency:CHFEUR""), IF($D4=""Libra Esterlina"", 'Original Data'!G4*GOOGLEFINANCE(""Curre"&"ncy:GBPEUR""), IF($D4=""Iene"",'Original Data'!G4*GOOGLEFINANCE(""Currency:JPYEUR""), IF($D4=""HKD"",'Original Data'!G4*GOOGLEFINANCE(""Currency:HKDEUR""), IF($D4=""KRW"",'Original Data'!G4*GOOGLEFINANCE(""Currency:KRWEUR""),"""")))))))"),49.57) -> 49.57 | H4: 2.44 | I4: 4.22 | J4: 0.0766 | K4: 0.0541 | L4: 0.035 | M4: 0.1255 | N4: =IFERROR(__xludf.DUMMYFUNCTION("IF('Original Data'!N4=""-"",""-"", IF($D4=""Euro"",'Original Data'!N4, IF($D4=""Dolar"",'Original Data'!N4*GOOGLEFINANCE(""Currency:USDEUR""), IF($D4=""Franco Suíço"",'Original Data'!N4*GOOGLEFINANCE(""Currency:CHFEUR""), IF($D4=""Libra Esterlina"", 'Orig"&"inal Data'!N4*GOOGLEFINANCE(""Currency:GBPEUR""), IF($D4=""Iene"",'Original Data'!N4*GOOGLEFINANCE(""Currency:JPYEUR""), IF($D4=""HKD"",'Original Data'!N4*GOOGLEFINANCE(""Currency:HKDEUR""), IF($D4=""KRW"",'Original Data'!N4*GOOGLEFINANCE(""Currency:KRWEU"&"R""),""""))))))))"),18.77) -> 18.77 | O4: =IFERROR(__xludf.DUMMYFUNCTION("IF('Original Data'!O4=""-"",""-"", IF($D4=""Euro"",'Original Data'!O4, IF($D4=""Dolar"",'Original Data'!O4*GOOGLEFINANCE(""Currency:USDEUR""), IF($D4=""Franco Suíço"",'Original Data'!O4*GOOGLEFINANCE(""Currency:CHFEUR""), IF($D4=""Libra Esterlina"", 'Orig"&"inal Data'!O4*GOOGLEFINANCE(""Currency:GBPEUR""), IF($D4=""Iene"",'Original Data'!O4*GOOGLEFINANCE(""Currency:JPYEUR""), IF($D4=""HKD"",'Original Data'!O4*GOOGLEFINANCE(""Currency:HKDEUR""), IF($D4=""KRW"",'Original Data'!O4*GOOGLEFINANCE(""Currency:KRWEU"&"R""),""""))))))))"),96.86) -> 96.86 | P4: =IFERROR(__xludf.DUMMYFUNCTION("IF('Original Data'!P4=""-"",""-"", IF($D4=""Euro"",'Original Data'!P4, IF($D4=""Dolar"",'Original Data'!P4*GOOGLEFINANCE(""Currency:USDEUR""), IF($D4=""Franco Suíço"",'Original Data'!P4*GOOGLEFINANCE(""Currency:CHFEUR""), IF($D4=""Libra Esterlina"", 'Orig"&"inal Data'!P4*GOOGLEFINANCE(""Currency:GBPEUR""), IF($D4=""Iene"",'Original Data'!P4*GOOGLEFINANCE(""Currency:JPYEUR""), IF($D4=""HKD"",'Original Data'!P4*GOOGLEFINANCE(""Currency:HKDEUR""), IF($D4=""KRW"",'Original Data'!P4*GOOGLEFINANCE(""Currency:KRWEU"&"R""),""""))))))))"),104.21) -> 104.21 | Q4: =IFERROR(__xludf.DUMMYFUNCTION("IF('Original Data'!Q4=""-"",""-"", IF($D4=""Euro"",'Original Data'!Q4, IF($D4=""Dolar"",'Original Data'!Q4*GOOGLEFINANCE(""Currency:USDEUR""), IF($D4=""Franco Suíço"",'Original Data'!Q4*GOOGLEFINANCE(""Currency:CHFEUR""), IF($D4=""Libra Esterlina"", 'Orig"&"inal Data'!Q4*GOOGLEFINANCE(""Currency:GBPEUR""), IF($D4=""Iene"",'Original Data'!Q4*GOOGLEFINANCE(""Currency:JPYEUR""), IF($D4=""HKD"",'Original Data'!Q4*GOOGLEFINANCE(""Currency:HKDEUR""), IF($D4=""KRW"",'Original Data'!Q4*GOOGLEFINANCE(""Currency:KRWEU"&"R""),""""))))))))"),98.99) -> 98.99 | R4: =IFERROR(__xludf.DUMMYFUNCTION("IF('Original Data'!R4=""-"",""-"", IF($D4=""Euro"",'Original Data'!R4, IF($D4=""Dolar"",'Original Data'!R4*GOOGLEFINANCE(""Currency:USDEUR""), IF($D4=""Franco Suíço"",'Original Data'!R4*GOOGLEFINANCE(""Currency:CHFEUR""), IF($D4=""Libra Esterlina"", 'Orig"&"inal Data'!R4*GOOGLEFINANCE(""Currency:GBPEUR""), IF($D4=""Iene"",'Original Data'!R4*GOOGLEFINANCE(""Currency:JPYEUR""), IF($D4=""HKD"",'Original Data'!R4*GOOGLEFINANCE(""Currency:HKDEUR""), IF($D4=""KRW"",'Original Data'!R4*GOOGLEFINANCE(""Currency:KRWEU"&"R""),""""))))))))"),111.24) -> 111.24 | S4: =IFERROR(__xludf.DUMMYFUNCTION("IF('Original Data'!S4=""-"",""-"", IF($D4=""Euro"",'Original Data'!S4, IF($D4=""Dolar"",'Original Data'!S4*GOOGLEFINANCE(""Currency:USDEUR""), IF($D4=""Franco Suíço"",'Original Data'!S4*GOOGLEFINANCE(""Currency:CHFEUR""), IF($D4=""Libra Esterlina"", 'Orig"&"inal Data'!S4*GOOGLEFINANCE(""Currency:GBPEUR""), IF($D4=""Iene"",'Original Data'!S4*GOOGLEFINANCE(""Currency:JPYEUR""), IF($D4=""HKD"",'Original Data'!S4*GOOGLEFINANCE(""Currency:HKDEUR""), IF($D4=""KRW"",'Original Data'!S4*GOOGLEFINANCE(""Currency:KRWEU"&"R""),""""))))))))"),17.4) -> 17.4 | T4: =IFERROR(__xludf.DUMMYFUNCTION("IF('Original Data'!T4=""-"",""-"", IF($D4=""Euro"",'Original Data'!T4, IF($D4=""Dolar"",'Original Data'!T4*GOOGLEFINANCE(""Currency:USDEUR""), IF($D4=""Franco Suíço"",'Original Data'!T4*GOOGLEFINANCE(""Currency:CHFEUR""), IF($D4=""Libra Esterlina"", 'Orig"&"inal Data'!T4*GOOGLEFINANCE(""Currency:GBPEUR""), IF($D4=""Iene"",'Original Data'!T4*GOOGLEFINANCE(""Currency:JPYEUR""), IF($D4=""HKD"",'Original Data'!T4*GOOGLEFINANCE(""Currency:HKDEUR""), IF($D4=""KRW"",'Original Data'!T4*GOOGLEFINANCE(""Currency:KRWEU"&"R""),""""))))))))"),17.98) -> 17.98 | U4: =IFERROR(__xludf.DUMMYFUNCTION("IF('Original Data'!U4=""-"",""-"", IF($D4=""Euro"",'Original Data'!U4, IF($D4=""Dolar"",'Original Data'!U4*GOOGLEFINANCE(""Currency:USDEUR""), IF($D4=""Franco Suíço"",'Original Data'!U4*GOOGLEFINANCE(""Currency:CHFEUR""), IF($D4=""Libra Esterlina"", 'Orig"&"inal Data'!U4*GOOGLEFINANCE(""Currency:GBPEUR""), IF($D4=""Iene"",'Original Data'!U4*GOOGLEFINANCE(""Currency:JPYEUR""), IF($D4=""HKD"",'Original Data'!U4*GOOGLEFINANCE(""Currency:HKDEUR""), IF($D4=""KRW"",'Original Data'!U4*GOOGLEFINANCE(""Currency:KRWEU"&"R""),""""))))))))"),11.0) -> 11 | V4: =IFERROR(__xludf.DUMMYFUNCTION("IF('Original Data'!V4=""-"",""-"", IF($D4=""Euro"",'Original Data'!V4, IF($D4=""Dolar"",'Original Data'!V4*GOOGLEFINANCE(""Currency:USDEUR""), IF($D4=""Franco Suíço"",'Original Data'!V4*GOOGLEFINANCE(""Currency:CHFEUR""), IF($D4=""Libra Esterlina"", 'Orig"&"inal Data'!V4*GOOGLEFINANCE(""Currency:GBPEUR""), IF($D4=""Iene"",'Original Data'!V4*GOOGLEFINANCE(""Currency:JPYEUR""), IF($D4=""HKD"",'Original Data'!V4*GOOGLEFINANCE(""Currency:HKDEUR""), IF($D4=""KRW"",'Original Data'!V4*GOOGLEFINANCE(""Currency:KRWEU"&"R""),""""))))))))"),19.94) -> 19.94 | W4: A | X4: A- | Y4: Declined to participate | Z4: Declined to participate | AA4: Declined to participate | AB4: Declined to participate | AC4: 24 | AD4: 7.2 | AE4: 7.5 | AF4: 9.2 | AG4: 3
A5: WALT DISNEY CO | B5: DIS US Equity | C5: US2546871060 | D5: Dolar | E5: =IFERROR(__xludf.DUMMYFUNCTION("IF($D5=""Euro"",'Original Data'!E5, IF($D5=""Dolar"",'Original Data'!E5*GOOGLEFINANCE(""Currency:USDEUR""), IF($D5=""Franco Suíço"",'Original Data'!E5*GOOGLEFINANCE(""Currency:CHFEUR""), IF($D5=""Libra Esterlina"", 'Original Data'!E5*GOOGLEFINANCE(""Curre"&"ncy:GBPEUR""), IF($D5=""Iene"",'Original Data'!E5*GOOGLEFINANCE(""Currency:JPYEUR""), IF($D5=""HKD"",'Original Data'!E5*GOOGLEFINANCE(""Currency:HKDEUR""), IF($D5=""KRW"",'Original Data'!E5*GOOGLEFINANCE(""Currency:KRWEUR""),"""")))))))"),1.09361) -> 1.09361 | F5: =IFERROR(__xludf.DUMMYFUNCTION("IF($D5=""Euro"",'Original Data'!F5, IF($D5=""Dolar"",'Original Data'!F5*GOOGLEFINANCE(""Currency:USDEUR""), IF($D5=""Franco Suíço"",'Original Data'!F5*GOOGLEFINANCE(""Currency:CHFEUR""), IF($D5=""Libra Esterlina"", 'Original Data'!F5*GOOGLEFINANCE(""Curre"&"ncy:GBPEUR""), IF($D5=""Iene"",'Original Data'!F5*GOOGLEFINANCE(""Currency:JPYEUR""), IF($D5=""HKD"",'Original Data'!F5*GOOGLEFINANCE(""Currency:HKDEUR""), IF($D5=""KRW"",'Original Data'!F5*GOOGLEFINANCE(""Currency:KRWEUR""),"""")))))))"),127.39178) -> 127.39178 | G5: =IFERROR(__xludf.DUMMYFUNCTION("IF($D5=""Euro"",'Original Data'!G5, IF($D5=""Dolar"",'Original Data'!G5*GOOGLEFINANCE(""Currency:USDEUR""), IF($D5=""Franco Suíço"",'Original Data'!G5*GOOGLEFINANCE(""Currency:CHFEUR""), IF($D5=""Libra Esterlina"", 'Original Data'!G5*GOOGLEFINANCE(""Curre"&"ncy:GBPEUR""), IF($D5=""Iene"",'Original Data'!G5*GOOGLEFINANCE(""Currency:JPYEUR""), IF($D5=""HKD"",'Original Data'!G5*GOOGLEFINANCE(""Currency:HKDEUR""), IF($D5=""KRW"",'Original Data'!G5*GOOGLEFINANCE(""Currency:KRWEUR""),"""")))))))"),234.42771) -> 234.42771 | H5: 12.41 | I5: 83.15 | J5: - | K5: 0.0554 | L5: 0.043 | M5: 0.0897 | N5: =IFERROR(__xludf.DUMMYFUNCTION("IF('Original Data'!N5=""-"",""-"", IF($D5=""Euro"",'Original Data'!N5, IF($D5=""Dolar"",'Original Data'!N5*GOOGLEFINANCE(""Currency:USDEUR""), IF($D5=""Franco Suíço"",'Original Data'!N5*GOOGLEFINANCE(""Currency:CHFEUR""), IF($D5=""Libra Esterlina"", 'Orig"&"inal Data'!N5*GOOGLEFINANCE(""Currency:GBPEUR""), IF($D5=""Iene"",'Original Data'!N5*GOOGLEFINANCE(""Currency:JPYEUR""), IF($D5=""HKD"",'Original Data'!N5*GOOGLEFINANCE(""Currency:HKDEUR""), IF($D5=""KRW"",'Original Data'!N5*GOOGLEFINANCE(""Currency:KRWEU"&"R""),""""))))))))"),1.02009) -> 1.02009 | O5: =IFERROR(__xludf.DUMMYFUNCTION("IF('Original Data'!O5=""-"",""-"", IF($D5=""Euro"",'Original Data'!O5, IF($D5=""Dolar"",'Original Data'!O5*GOOGLEFINANCE(""Currency:USDEUR""), IF($D5=""Franco Suíço"",'Original Data'!O5*GOOGLEFINANCE(""Currency:CHFEUR""), IF($D5=""Libra Esterlina"", 'Orig"&"inal Data'!O5*GOOGLEFINANCE(""Currency:GBPEUR""), IF($D5=""Iene"",'Original Data'!O5*GOOGLEFINANCE(""Currency:JPYEUR""), IF($D5=""HKD"",'Original Data'!O5*GOOGLEFINANCE(""Currency:HKDEUR""), IF($D5=""KRW"",'Original Data'!O5*GOOGLEFINANCE(""Currency:KRWEU"&"R""),""""))))))))"),54.65293) -> 54.65293 | P5: =IFERROR(__xludf.DUMMYFUNCTION("IF('Original Data'!P5=""-"",""-"", IF($D5=""Euro"",'Original Data'!P5, IF($D5=""Dolar"",'Original Data'!P5*GOOGLEFINANCE(""Currency:USDEUR""), IF($D5=""Franco Suíço"",'Original Data'!P5*GOOGLEFINANCE(""Currency:CHFEUR""), IF($D5=""Libra Esterlina"", 'Orig"&"inal Data'!P5*GOOGLEFINANCE(""Currency:GBPEUR""), IF($D5=""Iene"",'Original Data'!P5*GOOGLEFINANCE(""Currency:JPYEUR""), IF($D5=""HKD"",'Original Data'!P5*GOOGLEFINANCE(""Currency:HKDEUR""), IF($D5=""KRW"",'Original Data'!P5*GOOGLEFINANCE(""Currency:KRWEU"&"R""),""""))))))))"),63.79698) -> 63.79698 | Q5: =IFERROR(__xludf.DUMMYFUNCTION("IF('Original Data'!Q5=""-"",""-"", IF($D5=""Euro"",'Original Data'!Q5, IF($D5=""Dolar"",'Original Data'!Q5*GOOGLEFINANCE(""Currency:USDEUR""), IF($D5=""Franco Suíço"",'Original Data'!Q5*GOOGLEFINANCE(""Currency:CHFEUR""), IF($D5=""Libra Esterlina"", 'Orig"&"inal Data'!Q5*GOOGLEFINANCE(""Currency:GBPEUR""), IF($D5=""Iene"",'Original Data'!Q5*GOOGLEFINANCE(""Currency:JPYEUR""), IF($D5=""HKD"",'Original Data'!Q5*GOOGLEFINANCE(""Currency:HKDEUR""), IF($D5=""KRW"",'Original Data'!Q5*GOOGLEFINANCE(""Currency:KRWEU"&"R""),""""))))))))"),59.85446999999999) -> 59.85447 | R5: =IFERROR(__xludf.DUMMYFUNCTION("IF('Original Data'!R5=""-"",""-"", IF($D5=""Euro"",'Original Data'!R5, IF($D5=""Dolar"",'Original Data'!R5*GOOGLEFINANCE(""Currency:USDEUR""), IF($D5=""Franco Suíço"",'Original Data'!R5*GOOGLEFINANCE(""Currency:CHFEUR""), IF($D5=""Libra Esterlina"", 'Orig"&"inal Data'!R5*GOOGLEFINANCE(""Currency:GBPEUR""), IF($D5=""Iene"",'Original Data'!R5*GOOGLEFINANCE(""Currency:JPYEUR""), IF($D5=""HKD"",'Original Data'!R5*GOOGLEFINANCE(""Currency:HKDEUR""), IF($D5=""KRW"",'Original Data'!R5*GOOGLEFINANCE(""Currency:KRWEU"&"R""),""""))))))))"),61.93140999999999) -> 61.93141 | S5: =IFERROR(__xludf.DUMMYFUNCTION("IF('Original Data'!S5=""-"",""-"", IF($D5=""Euro"",'Original Data'!S5, IF($D5=""Dolar"",'Original Data'!S5*GOOGLEFINANCE(""Currency:USDEUR""), IF($D5=""Franco Suíço"",'Original Data'!S5*GOOGLEFINANCE(""Currency:CHFEUR""), IF($D5=""Libra Esterlina"", 'Orig"&"inal Data'!S5*GOOGLEFINANCE(""Currency:GBPEUR""), IF($D5=""Iene"",'Original Data'!S5*GOOGLEFINANCE(""Currency:JPYEUR""), IF($D5=""HKD"",'Original Data'!S5*GOOGLEFINANCE(""Currency:HKDEUR""), IF($D5=""KRW"",'Original Data'!S5*GOOGLEFINANCE(""Currency:KRWEU"&"R""),""""))))))))"),16.47767) -> 16.47767 | T5: =IFERROR(__xludf.DUMMYFUNCTION("IF('Original Data'!T5=""-"",""-"", IF($D5=""Euro"",'Original Data'!T5, IF($D5=""Dolar"",'Original Data'!T5*GOOGLEFINANCE(""Currency:USDEUR""), IF($D5=""Franco Suíço"",'Original Data'!T5*GOOGLEFINANCE(""Currency:CHFEUR""), IF($D5=""Libra Esterlina"", 'Orig"&"inal Data'!T5*GOOGLEFINANCE(""Currency:GBPEUR""), IF($D5=""Iene"",'Original Data'!T5*GOOGLEFINANCE(""Currency:JPYEUR""), IF($D5=""HKD"",'Original Data'!T5*GOOGLEFINANCE(""Currency:HKDEUR""), IF($D5=""KRW"",'Original Data'!T5*GOOGLEFINANCE(""Currency:KRWEU"&"R""),""""))))))))"),14.59372) -> 14.59372 | U5: =IFERROR(__xludf.DUMMYFUNCTION("IF('Original Data'!U5=""-"",""-"", IF($D5=""Euro"",'Original Data'!U5, IF($D5=""Dolar"",'Original Data'!U5*GOOGLEFINANCE(""Currency:USDEUR""), IF($D5=""Franco Suíço"",'Original Data'!U5*GOOGLEFINANCE(""Currency:CHFEUR""), IF($D5=""Libra Esterlina"", 'Orig"&"inal Data'!U5*GOOGLEFINANCE(""Currency:GBPEUR""), IF($D5=""Iene"",'Original Data'!U5*GOOGLEFINANCE(""Currency:JPYEUR""), IF($D5=""HKD"",'Original Data'!U5*GOOGLEFINANCE(""Currency:HKDEUR""), IF($D5=""KRW"",'Original Data'!U5*GOOGLEFINANCE(""Currency:KRWEU"&"R""),""""))))))))"),8.197479999999999) -> 8.19748 | V5: =IFERROR(__xludf.DUMMYFUNCTION("IF('Original Data'!V5=""-"",""-"", IF($D5=""Euro"",'Original Data'!V5, IF($D5=""Dolar"",'Original Data'!V5*GOOGLEFINANCE(""Currency:USDEUR""), IF($D5=""Franco Suíço"",'Original Data'!V5*GOOGLEFINANCE(""Currency:CHFEUR""), IF($D5=""Libra Esterlina"", 'Orig"&"inal Data'!V5*GOOGLEFINANCE(""Currency:GBPEUR""), IF($D5=""Iene"",'Original Data'!V5*GOOGLEFINANCE(""Currency:JPYEUR""), IF($D5=""HKD"",'Original Data'!V5*GOOGLEFINANCE(""Currency:HKDEUR""), IF($D5=""KRW"",'Original Data'!V5*GOOGLEFINANCE(""Currency:KRWEU"&"R""),""""))))))))"),8.133149999999999) -> 8.13315 | W5: B- | X5: B | Y5: Not Scored | Z5: Not Scored | AA5: - | AB5: - | AC5: 14 | AD5: 0.1 | AE5: 7.1 | AF5: 7.2 | AG5: 2
A6: ACCENTURE PLC-A | B6: ACN US Equity | C6: IE00B4BNMY34 | D6: Dolar | E6: =IFERROR(__xludf.DUMMYFUNCTION("IF($D6=""Euro"",'Original Data'!E6, IF($D6=""Dolar"",'Original Data'!E6*GOOGLEFINANCE(""Currency:USDEUR""), IF($D6=""Franco Suíço"",'Original Data'!E6*GOOGLEFINANCE(""Currency:CHFEUR""), IF($D6=""Libra Esterlina"", 'Original Data'!E6*GOOGLEFINANCE(""Curre"&"ncy:GBPEUR""), IF($D6=""Iene"",'Original Data'!E6*GOOGLEFINANCE(""Currency:JPYEUR""), IF($D6=""HKD"",'Original Data'!E6*GOOGLEFINANCE(""Currency:HKDEUR""), IF($D6=""KRW"",'Original Data'!E6*GOOGLEFINANCE(""Currency:KRWEUR""),"""")))))))"),16.82689) -> 16.82689 | F6: =IFERROR(__xludf.DUMMYFUNCTION("IF($D6=""Euro"",'Original Data'!F6, IF($D6=""Dolar"",'Original Data'!F6*GOOGLEFINANCE(""Currency:USDEUR""), IF($D6=""Franco Suíço"",'Original Data'!F6*GOOGLEFINANCE(""Currency:CHFEUR""), IF($D6=""Libra Esterlina"", 'Original Data'!F6*GOOGLEFINANCE(""Curre"&"ncy:GBPEUR""), IF($D6=""Iene"",'Original Data'!F6*GOOGLEFINANCE(""Currency:JPYEUR""), IF($D6=""HKD"",'Original Data'!F6*GOOGLEFINANCE(""Currency:HKDEUR""), IF($D6=""KRW"",'Original Data'!F6*GOOGLEFINANCE(""Currency:KRWEUR""),"""")))))))"),298.27063999999996) -> 298.27064 | G6: =IFERROR(__xludf.DUMMYFUNCTION("IF($D6=""Euro"",'Original Data'!G6, IF($D6=""Dolar"",'Original Data'!G6*GOOGLEFINANCE(""Currency:USDEUR""), IF($D6=""Franco Suíço"",'Original Data'!G6*GOOGLEFINANCE(""Currency:CHFEUR""), IF($D6=""Libra Esterlina"", 'Original Data'!G6*GOOGLEFINANCE(""Curre"&"ncy:GBPEUR""), IF($D6=""Iene"",'Original Data'!G6*GOOGLEFINANCE(""Currency:JPYEUR""), IF($D6=""HKD"",'Original Data'!G6*GOOGLEFINANCE(""Currency:HKDEUR""), IF($D6=""KRW"",'Original Data'!G6*GOOGLEFINANCE(""Currency:KRWEUR""),"""")))))))"),197.54824) -> 197.54824 | H6: 2.86 | I6: 33 | J6: 0.0118 | K6: 0.2756 | L6: 0.1648 | M6: 0.3653 | N6: =IFERROR(__xludf.DUMMYFUNCTION("IF('Original Data'!N6=""-"",""-"", IF($D6=""Euro"",'Original Data'!N6, IF($D6=""Dolar"",'Original Data'!N6*GOOGLEFINANCE(""Currency:USDEUR""), IF($D6=""Franco Suíço"",'Original Data'!N6*GOOGLEFINANCE(""Currency:CHFEUR""), IF($D6=""Libra Esterlina"", 'Orig"&"inal Data'!N6*GOOGLEFINANCE(""Currency:GBPEUR""), IF($D6=""Iene"",'Original Data'!N6*GOOGLEFINANCE(""Currency:JPYEUR""), IF($D6=""HKD"",'Original Data'!N6*GOOGLEFINANCE(""Currency:HKDEUR""), IF($D6=""KRW"",'Original Data'!N6*GOOGLEFINANCE(""Currency:KRWEU"&"R""),""""))))))))"),9.11648) -> 9.11648 | O6: =IFERROR(__xludf.DUMMYFUNCTION("IF('Original Data'!O6=""-"",""-"", IF($D6=""Euro"",'Original Data'!O6, IF($D6=""Dolar"",'Original Data'!O6*GOOGLEFINANCE(""Currency:USDEUR""), IF($D6=""Franco Suíço"",'Original Data'!O6*GOOGLEFINANCE(""Currency:CHFEUR""), IF($D6=""Libra Esterlina"", 'Orig"&"inal Data'!O6*GOOGLEFINANCE(""Currency:GBPEUR""), IF($D6=""Iene"",'Original Data'!O6*GOOGLEFINANCE(""Currency:JPYEUR""), IF($D6=""HKD"",'Original Data'!O6*GOOGLEFINANCE(""Currency:HKDEUR""), IF($D6=""KRW"",'Original Data'!O6*GOOGLEFINANCE(""Currency:KRWEU"&"R""),""""))))))))"),37.66981) -> 37.66981 | P6: =IFERROR(__xludf.DUMMYFUNCTION("IF('Original Data'!P6=""-"",""-"", IF($D6=""Euro"",'Original Data'!P6, IF($D6=""Dolar"",'Original Data'!P6*GOOGLEFINANCE(""Currency:USDEUR""), IF($D6=""Franco Suíço"",'Original Data'!P6*GOOGLEFINANCE(""Currency:CHFEUR""), IF($D6=""Libra Esterlina"", 'Orig"&"inal Data'!P6*GOOGLEFINANCE(""Currency:GBPEUR""), IF($D6=""Iene"",'Original Data'!P6*GOOGLEFINANCE(""Currency:JPYEUR""), IF($D6=""HKD"",'Original Data'!P6*GOOGLEFINANCE(""Currency:HKDEUR""), IF($D6=""KRW"",'Original Data'!P6*GOOGLEFINANCE(""Currency:KRWEU"&"R""),""""))))))))"),39.719179999999994) -> 39.71918 | Q6: =IFERROR(__xludf.DUMMYFUNCTION("IF('Original Data'!Q6=""-"",""-"", IF($D6=""Euro"",'Original Data'!Q6, IF($D6=""Dolar"",'Original Data'!Q6*GOOGLEFINANCE(""Currency:USDEUR""), IF($D6=""Franco Suíço"",'Original Data'!Q6*GOOGLEFINANCE(""Currency:CHFEUR""), IF($D6=""Libra Esterlina"", 'Orig"&"inal Data'!Q6*GOOGLEFINANCE(""Currency:GBPEUR""), IF($D6=""Iene"",'Original Data'!Q6*GOOGLEFINANCE(""Currency:JPYEUR""), IF($D6=""HKD"",'Original Data'!Q6*GOOGLEFINANCE(""Currency:HKDEUR""), IF($D6=""KRW"",'Original Data'!Q6*GOOGLEFINANCE(""Currency:KRWEU"&"R""),""""))))))))"),40.73927) -> 40.73927 | R6: =IFERROR(__xludf.DUMMYFUNCTION("IF('Original Data'!R6=""-"",""-"", IF($D6=""Euro"",'Original Data'!R6, IF($D6=""Dolar"",'Original Data'!R6*GOOGLEFINANCE(""Currency:USDEUR""), IF($D6=""Franco Suíço"",'Original Data'!R6*GOOGLEFINANCE(""Currency:CHFEUR""), IF($D6=""Libra Esterlina"", 'Orig"&"inal Data'!R6*GOOGLEFINANCE(""Currency:GBPEUR""), IF($D6=""Iene"",'Original Data'!R6*GOOGLEFINANCE(""Currency:JPYEUR""), IF($D6=""HKD"",'Original Data'!R6*GOOGLEFINANCE(""Currency:HKDEUR""), IF($D6=""KRW"",'Original Data'!R6*GOOGLEFINANCE(""Currency:KRWEU"&"R""),""""))))))))"),46.43707) -> 46.43707 | S6: =IFERROR(__xludf.DUMMYFUNCTION("IF('Original Data'!S6=""-"",""-"", IF($D6=""Euro"",'Original Data'!S6, IF($D6=""Dolar"",'Original Data'!S6*GOOGLEFINANCE(""Currency:USDEUR""), IF($D6=""Franco Suíço"",'Original Data'!S6*GOOGLEFINANCE(""Currency:CHFEUR""), IF($D6=""Libra Esterlina"", 'Orig"&"inal Data'!S6*GOOGLEFINANCE(""Currency:GBPEUR""), IF($D6=""Iene"",'Original Data'!S6*GOOGLEFINANCE(""Currency:JPYEUR""), IF($D6=""HKD"",'Original Data'!S6*GOOGLEFINANCE(""Currency:HKDEUR""), IF($D6=""KRW"",'Original Data'!S6*GOOGLEFINANCE(""Currency:KRWEU"&"R""),""""))))))))"),6.35948) -> 6.35948 | T6: =IFERROR(__xludf.DUMMYFUNCTION("IF('Original Data'!T6=""-"",""-"", IF($D6=""Euro"",'Original Data'!T6, IF($D6=""Dolar"",'Original Data'!T6*GOOGLEFINANCE(""Currency:USDEUR""), IF($D6=""Franco Suíço"",'Original Data'!T6*GOOGLEFINANCE(""Currency:CHFEUR""), IF($D6=""Libra Esterlina"", 'Orig"&"inal Data'!T6*GOOGLEFINANCE(""Currency:GBPEUR""), IF($D6=""Iene"",'Original Data'!T6*GOOGLEFINANCE(""Currency:JPYEUR""), IF($D6=""HKD"",'Original Data'!T6*GOOGLEFINANCE(""Currency:HKDEUR""), IF($D6=""KRW"",'Original Data'!T6*GOOGLEFINANCE(""Currency:KRWEU"&"R""),""""))))))))"),6.662749999999999) -> 6.66275 | U6: =IFERROR(__xludf.DUMMYFUNCTION("IF('Original Data'!U6=""-"",""-"", IF($D6=""Euro"",'Original Data'!U6, IF($D6=""Dolar"",'Original Data'!U6*GOOGLEFINANCE(""Currency:USDEUR""), IF($D6=""Franco Suíço"",'Original Data'!U6*GOOGLEFINANCE(""Currency:CHFEUR""), IF($D6=""Libra Esterlina"", 'Orig"&"inal Data'!U6*GOOGLEFINANCE(""Currency:GBPEUR""), IF($D6=""Iene"",'Original Data'!U6*GOOGLEFINANCE(""Currency:JPYEUR""), IF($D6=""HKD"",'Original Data'!U6*GOOGLEFINANCE(""Currency:HKDEUR""), IF($D6=""KRW"",'Original Data'!U6*GOOGLEFINANCE(""Currency:KRWEU"&"R""),""""))))))))"),7.664459999999999) -> 7.66446 | V6: =IFERROR(__xludf.DUMMYFUNCTION("IF('Original Data'!V6=""-"",""-"", IF($D6=""Euro"",'Original Data'!V6, IF($D6=""Dolar"",'Original Data'!V6*GOOGLEFINANCE(""Currency:USDEUR""), IF($D6=""Franco Suíço"",'Original Data'!V6*GOOGLEFINANCE(""Currency:CHFEUR""), IF($D6=""Libra Esterlina"", 'Orig"&"inal Data'!V6*GOOGLEFINANCE(""Currency:GBPEUR""), IF($D6=""Iene"",'Original Data'!V6*GOOGLEFINANCE(""Currency:JPYEUR""), IF($D6=""HKD"",'Original Data'!V6*GOOGLEFINANCE(""Currency:HKDEUR""), IF($D6=""KRW"",'Original Data'!V6*GOOGLEFINANCE(""Currency:KRWEU"&"R""),""""))))))))"),8.840779999999999) -> 8.84078 | W6: A | X6: A- | Y6: - | Z6: - | AA6: - | AB6: - | AC6: 9 | AD6: 0.3 | AE6: 4.3 | AF6: 4.8 | AG6: 2
A7: MCDONALDS CORP | B7: MCD US Equity | C7: US5801351017 | D7: Dolar | E7: =IFERROR(__xludf.DUMMYFUNCTION("IF($D7=""Euro"",'Original Data'!E7, IF($D7=""Dolar"",'Original Data'!E7*GOOGLEFINANCE(""Currency:USDEUR""), IF($D7=""Franco Suíço"",'Original Data'!E7*GOOGLEFINANCE(""Currency:CHFEUR""), IF($D7=""Libra Esterlina"", 'Original Data'!E7*GOOGLEFINANCE(""Curre"&"ncy:GBPEUR""), IF($D7=""Iene"",'Original Data'!E7*GOOGLEFINANCE(""Currency:JPYEUR""), IF($D7=""HKD"",'Original Data'!E7*GOOGLEFINANCE(""Currency:HKDEUR""), IF($D7=""KRW"",'Original Data'!E7*GOOGLEFINANCE(""Currency:KRWEUR""),"""")))))))"),0.74439) -> 0.74439 | F7: =IFERROR(__xludf.DUMMYFUNCTION("IF($D7=""Euro"",'Original Data'!F7, IF($D7=""Dolar"",'Original Data'!F7*GOOGLEFINANCE(""Currency:USDEUR""), IF($D7=""Franco Suíço"",'Original Data'!F7*GOOGLEFINANCE(""Currency:CHFEUR""), IF($D7=""Libra Esterlina"", 'Original Data'!F7*GOOGLEFINANCE(""Curre"&"ncy:GBPEUR""), IF($D7=""Iene"",'Original Data'!F7*GOOGLEFINANCE(""Currency:JPYEUR""), IF($D7=""HKD"",'Original Data'!F7*GOOGLEFINANCE(""Currency:HKDEUR""), IF($D7=""KRW"",'Original Data'!F7*GOOGLEFINANCE(""Currency:KRWEUR""),"""")))))))"),216.25907999999998) -> 216.25908 | G7: =IFERROR(__xludf.DUMMYFUNCTION("IF($D7=""Euro"",'Original Data'!G7, IF($D7=""Dolar"",'Original Data'!G7*GOOGLEFINANCE(""Currency:USDEUR""), IF($D7=""Franco Suíço"",'Original Data'!G7*GOOGLEFINANCE(""Currency:CHFEUR""), IF($D7=""Libra Esterlina"", 'Original Data'!G7*GOOGLEFINANCE(""Curre"&"ncy:GBPEUR""), IF($D7=""Iene"",'Original Data'!G7*GOOGLEFINANCE(""Currency:JPYEUR""), IF($D7=""HKD"",'Original Data'!G7*GOOGLEFINANCE(""Currency:HKDEUR""), IF($D7=""KRW"",'Original Data'!G7*GOOGLEFINANCE(""Currency:KRWEUR""),"""")))))))"),162.71813999999998) -> 162.71814 | H7: 4.02 | I7: 23.73 | J7: 0.0232 | K7: 0.1595 | L7: 0.1447 | M7: -% | N7: =IFERROR(__xludf.DUMMYFUNCTION("IF('Original Data'!N7=""-"",""-"", IF($D7=""Euro"",'Original Data'!N7, IF($D7=""Dolar"",'Original Data'!N7*GOOGLEFINANCE(""Currency:USDEUR""), IF($D7=""Franco Suíço"",'Original Data'!N7*GOOGLEFINANCE(""Currency:CHFEUR""), IF($D7=""Libra Esterlina"", 'Orig"&"inal Data'!N7*GOOGLEFINANCE(""Currency:GBPEUR""), IF($D7=""Iene"",'Original Data'!N7*GOOGLEFINANCE(""Currency:JPYEUR""), IF($D7=""HKD"",'Original Data'!N7*GOOGLEFINANCE(""Currency:HKDEUR""), IF($D7=""KRW"",'Original Data'!N7*GOOGLEFINANCE(""Currency:KRWEU"&"R""),""""))))))))"),9.226759999999999) -> 9.22676 | O7: =IFERROR(__xludf.DUMMYFUNCTION("IF('Original Data'!O7=""-"",""-"", IF($D7=""Euro"",'Original Data'!O7, IF($D7=""Dolar"",'Original Data'!O7*GOOGLEFINANCE(""Currency:USDEUR""), IF($D7=""Franco Suíço"",'Original Data'!O7*GOOGLEFINANCE(""Currency:CHFEUR""), IF($D7=""Libra Esterlina"", 'Orig"&"inal Data'!O7*GOOGLEFINANCE(""Currency:GBPEUR""), IF($D7=""Iene"",'Original Data'!O7*GOOGLEFINANCE(""Currency:JPYEUR""), IF($D7=""HKD"",'Original Data'!O7*GOOGLEFINANCE(""Currency:HKDEUR""), IF($D7=""KRW"",'Original Data'!O7*GOOGLEFINANCE(""Currency:KRWEU"&"R""),""""))))))))"),19.32657) -> 19.32657 | P7: =IFERROR(__xludf.DUMMYFUNCTION("IF('Original Data'!P7=""-"",""-"", IF($D7=""Euro"",'Original Data'!P7, IF($D7=""Dolar"",'Original Data'!P7*GOOGLEFINANCE(""Currency:USDEUR""), IF($D7=""Franco Suíço"",'Original Data'!P7*GOOGLEFINANCE(""Currency:CHFEUR""), IF($D7=""Libra Esterlina"", 'Orig"&"inal Data'!P7*GOOGLEFINANCE(""Currency:GBPEUR""), IF($D7=""Iene"",'Original Data'!P7*GOOGLEFINANCE(""Currency:JPYEUR""), IF($D7=""HKD"",'Original Data'!P7*GOOGLEFINANCE(""Currency:HKDEUR""), IF($D7=""KRW"",'Original Data'!P7*GOOGLEFINANCE(""Currency:KRWEU"&"R""),""""))))))))"),19.629839999999998) -> 19.62984 | Q7: =IFERROR(__xludf.DUMMYFUNCTION("IF('Original Data'!Q7=""-"",""-"", IF($D7=""Euro"",'Original Data'!Q7, IF($D7=""Dolar"",'Original Data'!Q7*GOOGLEFINANCE(""Currency:USDEUR""), IF($D7=""Franco Suíço"",'Original Data'!Q7*GOOGLEFINANCE(""Currency:CHFEUR""), IF($D7=""Libra Esterlina"", 'Orig"&"inal Data'!Q7*GOOGLEFINANCE(""Currency:GBPEUR""), IF($D7=""Iene"",'Original Data'!Q7*GOOGLEFINANCE(""Currency:JPYEUR""), IF($D7=""HKD"",'Original Data'!Q7*GOOGLEFINANCE(""Currency:HKDEUR""), IF($D7=""KRW"",'Original Data'!Q7*GOOGLEFINANCE(""Currency:KRWEU"&"R""),""""))))))))"),17.65399) -> 17.65399 | R7: =IFERROR(__xludf.DUMMYFUNCTION("IF('Original Data'!R7=""-"",""-"", IF($D7=""Euro"",'Original Data'!R7, IF($D7=""Dolar"",'Original Data'!R7*GOOGLEFINANCE(""Currency:USDEUR""), IF($D7=""Franco Suíço"",'Original Data'!R7*GOOGLEFINANCE(""Currency:CHFEUR""), IF($D7=""Libra Esterlina"", 'Orig"&"inal Data'!R7*GOOGLEFINANCE(""Currency:GBPEUR""), IF($D7=""Iene"",'Original Data'!R7*GOOGLEFINANCE(""Currency:JPYEUR""), IF($D7=""HKD"",'Original Data'!R7*GOOGLEFINANCE(""Currency:HKDEUR""), IF($D7=""KRW"",'Original Data'!R7*GOOGLEFINANCE(""Currency:KRWEU"&"R""),""""))))))))"),21.33918) -> 21.33918 | S7: =IFERROR(__xludf.DUMMYFUNCTION("IF('Original Data'!S7=""-"",""-"", IF($D7=""Euro"",'Original Data'!S7, IF($D7=""Dolar"",'Original Data'!S7*GOOGLEFINANCE(""Currency:USDEUR""), IF($D7=""Franco Suíço"",'Original Data'!S7*GOOGLEFINANCE(""Currency:CHFEUR""), IF($D7=""Libra Esterlina"", 'Orig"&"inal Data'!S7*GOOGLEFINANCE(""Currency:GBPEUR""), IF($D7=""Iene"",'Original Data'!S7*GOOGLEFINANCE(""Currency:JPYEUR""), IF($D7=""HKD"",'Original Data'!S7*GOOGLEFINANCE(""Currency:HKDEUR""), IF($D7=""KRW"",'Original Data'!S7*GOOGLEFINANCE(""Currency:KRWEU"&"R""),""""))))))))"),9.25433) -> 9.25433 | T7: =IFERROR(__xludf.DUMMYFUNCTION("IF('Original Data'!T7=""-"",""-"", IF($D7=""Euro"",'Original Data'!T7, IF($D7=""Dolar"",'Original Data'!T7*GOOGLEFINANCE(""Currency:USDEUR""), IF($D7=""Franco Suíço"",'Original Data'!T7*GOOGLEFINANCE(""Currency:CHFEUR""), IF($D7=""Libra Esterlina"", 'Orig"&"inal Data'!T7*GOOGLEFINANCE(""Currency:GBPEUR""), IF($D7=""Iene"",'Original Data'!T7*GOOGLEFINANCE(""Currency:JPYEUR""), IF($D7=""HKD"",'Original Data'!T7*GOOGLEFINANCE(""Currency:HKDEUR""), IF($D7=""KRW"",'Original Data'!T7*GOOGLEFINANCE(""Currency:KRWEU"&"R""),""""))))))))"),9.6495) -> 9.6495 | U7: =IFERROR(__xludf.DUMMYFUNCTION("IF('Original Data'!U7=""-"",""-"", IF($D7=""Euro"",'Original Data'!U7, IF($D7=""Dolar"",'Original Data'!U7*GOOGLEFINANCE(""Currency:USDEUR""), IF($D7=""Franco Suíço"",'Original Data'!U7*GOOGLEFINANCE(""Currency:CHFEUR""), IF($D7=""Libra Esterlina"", 'Orig"&"inal Data'!U7*GOOGLEFINANCE(""Currency:GBPEUR""), IF($D7=""Iene"",'Original Data'!U7*GOOGLEFINANCE(""Currency:JPYEUR""), IF($D7=""HKD"",'Original Data'!U7*GOOGLEFINANCE(""Currency:HKDEUR""), IF($D7=""KRW"",'Original Data'!U7*GOOGLEFINANCE(""Currency:KRWEU"&"R""),""""))))))))"),8.18829) -> 8.18829 | V7: =IFERROR(__xludf.DUMMYFUNCTION("IF('Original Data'!V7=""-"",""-"", IF($D7=""Euro"",'Original Data'!V7, IF($D7=""Dolar"",'Original Data'!V7*GOOGLEFINANCE(""Currency:USDEUR""), IF($D7=""Franco Suíço"",'Original Data'!V7*GOOGLEFINANCE(""Currency:CHFEUR""), IF($D7=""Libra Esterlina"", 'Orig"&"inal Data'!V7*GOOGLEFINANCE(""Currency:GBPEUR""), IF($D7=""Iene"",'Original Data'!V7*GOOGLEFINANCE(""Currency:JPYEUR""), IF($D7=""HKD"",'Original Data'!V7*GOOGLEFINANCE(""Currency:HKDEUR""), IF($D7=""KRW"",'Original Data'!V7*GOOGLEFINANCE(""Currency:KRWEU"&"R""),""""))))))))"),10.69716) -> 10.69716 | W7: C | X7: C | Y7: D/C | Z7: B-/B | AA7: C | AB7: D | AC7: 24 | AD7: 4.1 | AE7: 14.4 | AF7: 5.9 | AG7: 3
A8: HYUNDAI MOTO-GDR | B8: HYUD LI Equity | C8: USY384721251 | D8: Dolar | E8: =IFERROR(__xludf.DUMMYFUNCTION("IF($D8=""Euro"",'Original Data'!E8, IF($D8=""Dolar"",'Original Data'!E8*GOOGLEFINANCE(""Currency:USDEUR""), IF($D8=""Franco Suíço"",'Original Data'!E8*GOOGLEFINANCE(""Currency:CHFEUR""), IF($D8=""Libra Esterlina"", 'Original Data'!E8*GOOGLEFINANCE(""Curre"&"ncy:GBPEUR""), IF($D8=""Iene"",'Original Data'!E8*GOOGLEFINANCE(""Currency:JPYEUR""), IF($D8=""HKD"",'Original Data'!E8*GOOGLEFINANCE(""Currency:HKDEUR""), IF($D8=""KRW"",'Original Data'!E8*GOOGLEFINANCE(""Currency:KRWEUR""),"""")))))))"),2.9408) -> 2.9408 | F8: =IFERROR(__xludf.DUMMYFUNCTION("IF($D8=""Euro"",'Original Data'!F8, IF($D8=""Dolar"",'Original Data'!F8*GOOGLEFINANCE(""Currency:USDEUR""), IF($D8=""Franco Suíço"",'Original Data'!F8*GOOGLEFINANCE(""Currency:CHFEUR""), IF($D8=""Libra Esterlina"", 'Original Data'!F8*GOOGLEFINANCE(""Curre"&"ncy:GBPEUR""), IF($D8=""Iene"",'Original Data'!F8*GOOGLEFINANCE(""Currency:JPYEUR""), IF($D8=""HKD"",'Original Data'!F8*GOOGLEFINANCE(""Currency:HKDEUR""), IF($D8=""KRW"",'Original Data'!F8*GOOGLEFINANCE(""Currency:KRWEUR""),"""")))))))"),31.337899999999998) -> 31.3379 | G8: =IFERROR(__xludf.DUMMYFUNCTION("IF($D8=""Euro"",'Original Data'!G8, IF($D8=""Dolar"",'Original Data'!G8*GOOGLEFINANCE(""Currency:USDEUR""), IF($D8=""Franco Suíço"",'Original Data'!G8*GOOGLEFINANCE(""Currency:CHFEUR""), IF($D8=""Libra Esterlina"", 'Original Data'!G8*GOOGLEFINANCE(""Curre"&"ncy:GBPEUR""), IF($D8=""Iene"",'Original Data'!G8*GOOGLEFINANCE(""Currency:JPYEUR""), IF($D8=""HKD"",'Original Data'!G8*GOOGLEFINANCE(""Currency:HKDEUR""), IF($D8=""KRW"",'Original Data'!G8*GOOGLEFINANCE(""Currency:KRWEUR""),"""")))))))"),29.69289) -> 29.69289 | H8: 0.007846 | I8: - | J8: 0.0521 | K8: 0.025 | L8: 0.0175 | M8: 0.0428 | N8: =IFERROR(__xludf.DUMMYFUNCTION("'Original Data'!N8*GOOGLEFINANCE(""Currency:KRWEUR"")"),14.282486201516004) -> 14.282486 | O8: =IFERROR(__xludf.DUMMYFUNCTION("'Original Data'!O8*GOOGLEFINANCE(""Currency:KRWEUR"")"),72.804408277503) -> 72.804408 | P8: =IFERROR(__xludf.DUMMYFUNCTION("'Original Data'!P8*GOOGLEFINANCE(""Currency:KRWEUR"")"),79.52759193622501) -> 79.527592 | Q8: =IFERROR(__xludf.DUMMYFUNCTION("'Original Data'!Q8*GOOGLEFINANCE(""Currency:KRWEUR"")"),78.2115324952) -> 78.211533 | R8: =IFERROR(__xludf.DUMMYFUNCTION("'Original Data'!R8*GOOGLEFINANCE(""Currency:KRWEUR"")"),88.4474668105093) -> 88.447467 | S8: =IFERROR(__xludf.DUMMYFUNCTION("'Original Data'!S8*GOOGLEFINANCE(""Currency:KRWEUR"")"),4.647569911734) -> 4.6475699 | T8: =IFERROR(__xludf.DUMMYFUNCTION("'Original Data'!T8*GOOGLEFINANCE(""Currency:KRWEUR"")"),5.730498823206) -> 5.7304988 | U8: =IFERROR(__xludf.DUMMYFUNCTION("'Original Data'!U8*GOOGLEFINANCE(""Currency:KRWEUR"")"),5.098790291514) -> 5.0987903 | V8: =IFERROR(__xludf.DUMMYFUNCTION("'Original Data'!V8*GOOGLEFINANCE(""Currency:KRWEUR"")"),8.603268574472) -> 8.6032686 | W8: A- | X8: B | Y8: No Response | Z8: No Response | AA8: A- | AB8: A- | AC8: - | AD8: - | AE8: - | AF8: - | AG8: -
A9: CATERPILLAR INC | B9: CAT US Equity | C9: US1491231015 | D9: Dolar | E9: =IFERROR(__xludf.DUMMYFUNCTION("IF($D9=""Euro"",'Original Data'!E9, IF($D9=""Dolar"",'Original Data'!E9*GOOGLEFINANCE(""Currency:USDEUR""), IF($D9=""Franco Suíço"",'Original Data'!E9*GOOGLEFINANCE(""Currency:CHFEUR""), IF($D9=""Libra Esterlina"", 'Original Data'!E9*GOOGLEFINANCE(""Curre"&"ncy:GBPEUR""), IF($D9=""Iene"",'Original Data'!E9*GOOGLEFINANCE(""Currency:JPYEUR""), IF($D9=""HKD"",'Original Data'!E9*GOOGLEFINANCE(""Currency:HKDEUR""), IF($D9=""KRW"",'Original Data'!E9*GOOGLEFINANCE(""Currency:KRWEUR""),"""")))))))"),5.54157) -> 5.54157 | F9: =IFERROR(__xludf.DUMMYFUNCTION("IF($D9=""Euro"",'Original Data'!F9, IF($D9=""Dolar"",'Original Data'!F9*GOOGLEFINANCE(""Currency:USDEUR""), IF($D9=""Franco Suíço"",'Original Data'!F9*GOOGLEFINANCE(""Currency:CHFEUR""), IF($D9=""Libra Esterlina"", 'Original Data'!F9*GOOGLEFINANCE(""Curre"&"ncy:GBPEUR""), IF($D9=""Iene"",'Original Data'!F9*GOOGLEFINANCE(""Currency:JPYEUR""), IF($D9=""HKD"",'Original Data'!F9*GOOGLEFINANCE(""Currency:HKDEUR""), IF($D9=""KRW"",'Original Data'!F9*GOOGLEFINANCE(""Currency:KRWEUR""),"""")))))))"),205.55272999999997) -> 205.55273 | G9: =IFERROR(__xludf.DUMMYFUNCTION("IF($D9=""Euro"",'Original Data'!G9, IF($D9=""Dolar"",'Original Data'!G9*GOOGLEFINANCE(""Currency:USDEUR""), IF($D9=""Franco Suíço"",'Original Data'!G9*GOOGLEFINANCE(""Currency:CHFEUR""), IF($D9=""Libra Esterlina"", 'Original Data'!G9*GOOGLEFINANCE(""Curre"&"ncy:GBPEUR""), IF($D9=""Iene"",'Original Data'!G9*GOOGLEFINANCE(""Currency:JPYEUR""), IF($D9=""HKD"",'Original Data'!G9*GOOGLEFINANCE(""Currency:HKDEUR""), IF($D9=""KRW"",'Original Data'!G9*GOOGLEFINANCE(""Currency:KRWEUR""),"""")))))))"),110.16971999999998) -> 110.16972 | H9: 4.2 | I9: 18.93 | J9: 0.0199 | K9: 0.0954 | L9: 0.0623 | M9: 0.3375 | N9: =IFERROR(__xludf.DUMMYFUNCTION("IF('Original Data'!N9=""-"",""-"", IF($D9=""Euro"",'Original Data'!N9, IF($D9=""Dolar"",'Original Data'!N9*GOOGLEFINANCE(""Currency:USDEUR""), IF($D9=""Franco Suíço"",'Original Data'!N9*GOOGLEFINANCE(""Currency:CHFEUR""), IF($D9=""Libra Esterlina"", 'Orig"&"inal Data'!N9*GOOGLEFINANCE(""Currency:GBPEUR""), IF($D9=""Iene"",'Original Data'!N9*GOOGLEFINANCE(""Currency:JPYEUR""), IF($D9=""HKD"",'Original Data'!N9*GOOGLEFINANCE(""Currency:HKDEUR""), IF($D9=""KRW"",'Original Data'!N9*GOOGLEFINANCE(""Currency:KRWEU"&"R""),""""))))))))"),10.899339999999999) -> 10.89934 | O9: =IFERROR(__xludf.DUMMYFUNCTION("IF('Original Data'!O9=""-"",""-"", IF($D9=""Euro"",'Original Data'!O9, IF($D9=""Dolar"",'Original Data'!O9*GOOGLEFINANCE(""Currency:USDEUR""), IF($D9=""Franco Suíço"",'Original Data'!O9*GOOGLEFINANCE(""Currency:CHFEUR""), IF($D9=""Libra Esterlina"", 'Orig"&"inal Data'!O9*GOOGLEFINANCE(""Currency:GBPEUR""), IF($D9=""Iene"",'Original Data'!O9*GOOGLEFINANCE(""Currency:JPYEUR""), IF($D9=""HKD"",'Original Data'!O9*GOOGLEFINANCE(""Currency:HKDEUR""), IF($D9=""KRW"",'Original Data'!O9*GOOGLEFINANCE(""Currency:KRWEU"&"R""),""""))))))))"),50.287679999999995) -> 50.28768 | P9: =IFERROR(__xludf.DUMMYFUNCTION("IF('Original Data'!P9=""-"",""-"", IF($D9=""Euro"",'Original Data'!P9, IF($D9=""Dolar"",'Original Data'!P9*GOOGLEFINANCE(""Currency:USDEUR""), IF($D9=""Franco Suíço"",'Original Data'!P9*GOOGLEFINANCE(""Currency:CHFEUR""), IF($D9=""Libra Esterlina"", 'Orig"&"inal Data'!P9*GOOGLEFINANCE(""Currency:GBPEUR""), IF($D9=""Iene"",'Original Data'!P9*GOOGLEFINANCE(""Currency:JPYEUR""), IF($D9=""HKD"",'Original Data'!P9*GOOGLEFINANCE(""Currency:HKDEUR""), IF($D9=""KRW"",'Original Data'!P9*GOOGLEFINANCE(""Currency:KRWEU"&"R""),""""))))))))"),49.433009999999996) -> 49.43301 | Q9: =IFERROR(__xludf.DUMMYFUNCTION("IF('Original Data'!Q9=""-"",""-"", IF($D9=""Euro"",'Original Data'!Q9, IF($D9=""Dolar"",'Original Data'!Q9*GOOGLEFINANCE(""Currency:USDEUR""), IF($D9=""Franco Suíço"",'Original Data'!Q9*GOOGLEFINANCE(""Currency:CHFEUR""), IF($D9=""Libra Esterlina"", 'Orig"&"inal Data'!Q9*GOOGLEFINANCE(""Currency:GBPEUR""), IF($D9=""Iene"",'Original Data'!Q9*GOOGLEFINANCE(""Currency:JPYEUR""), IF($D9=""HKD"",'Original Data'!Q9*GOOGLEFINANCE(""Currency:HKDEUR""), IF($D9=""KRW"",'Original Data'!Q9*GOOGLEFINANCE(""Currency:KRWEU"&"R""),""""))))))))"),38.368249999999996) -> 38.36825 | R9: =IFERROR(__xludf.DUMMYFUNCTION("IF('Original Data'!R9=""-"",""-"", IF($D9=""Euro"",'Original Data'!R9, IF($D9=""Dolar"",'Original Data'!R9*GOOGLEFINANCE(""Currency:USDEUR""), IF($D9=""Franco Suíço"",'Original Data'!R9*GOOGLEFINANCE(""Currency:CHFEUR""), IF($D9=""Libra Esterlina"", 'Orig"&"inal Data'!R9*GOOGLEFINANCE(""Currency:GBPEUR""), IF($D9=""Iene"",'Original Data'!R9*GOOGLEFINANCE(""Currency:JPYEUR""), IF($D9=""HKD"",'Original Data'!R9*GOOGLEFINANCE(""Currency:HKDEUR""), IF($D9=""KRW"",'Original Data'!R9*GOOGLEFINANCE(""Currency:KRWEU"&"R""),""""))))))))"),46.85061999999999) -> 46.85062 | S9: =IFERROR(__xludf.DUMMYFUNCTION("IF('Original Data'!S9=""-"",""-"", IF($D9=""Euro"",'Original Data'!S9, IF($D9=""Dolar"",'Original Data'!S9*GOOGLEFINANCE(""Currency:USDEUR""), IF($D9=""Franco Suíço"",'Original Data'!S9*GOOGLEFINANCE(""Currency:CHFEUR""), IF($D9=""Libra Esterlina"", 'Orig"&"inal Data'!S9*GOOGLEFINANCE(""Currency:GBPEUR""), IF($D9=""Iene"",'Original Data'!S9*GOOGLEFINANCE(""Currency:JPYEUR""), IF($D9=""HKD"",'Original Data'!S9*GOOGLEFINANCE(""Currency:HKDEUR""), IF($D9=""KRW"",'Original Data'!S9*GOOGLEFINANCE(""Currency:KRWEU"&"R""),""""))))))))"),10.504169999999998) -> 10.50417 | T9: =IFERROR(__xludf.DUMMYFUNCTION("IF('Original Data'!T9=""-"",""-"", IF($D9=""Euro"",'Original Data'!T9, IF($D9=""Dolar"",'Original Data'!T9*GOOGLEFINANCE(""Currency:USDEUR""), IF($D9=""Franco Suíço"",'Original Data'!T9*GOOGLEFINANCE(""Currency:CHFEUR""), IF($D9=""Libra Esterlina"", 'Orig"&"inal Data'!T9*GOOGLEFINANCE(""Currency:GBPEUR""), IF($D9=""Iene"",'Original Data'!T9*GOOGLEFINANCE(""Currency:JPYEUR""), IF($D9=""HKD"",'Original Data'!T9*GOOGLEFINANCE(""Currency:HKDEUR""), IF($D9=""KRW"",'Original Data'!T9*GOOGLEFINANCE(""Currency:KRWEU"&"R""),""""))))))))"),10.17333) -> 10.17333 | U9: =IFERROR(__xludf.DUMMYFUNCTION("IF('Original Data'!U9=""-"",""-"", IF($D9=""Euro"",'Original Data'!U9, IF($D9=""Dolar"",'Original Data'!U9*GOOGLEFINANCE(""Currency:USDEUR""), IF($D9=""Franco Suíço"",'Original Data'!U9*GOOGLEFINANCE(""Currency:CHFEUR""), IF($D9=""Libra Esterlina"", 'Orig"&"inal Data'!U9*GOOGLEFINANCE(""Currency:GBPEUR""), IF($D9=""Iene"",'Original Data'!U9*GOOGLEFINANCE(""Currency:JPYEUR""), IF($D9=""HKD"",'Original Data'!U9*GOOGLEFINANCE(""Currency:HKDEUR""), IF($D9=""KRW"",'Original Data'!U9*GOOGLEFINANCE(""Currency:KRWEU"&"R""),""""))))))))"),6.80979) -> 6.80979 | V9: =IFERROR(__xludf.DUMMYFUNCTION("IF('Original Data'!V9=""-"",""-"", IF($D9=""Euro"",'Original Data'!V9, IF($D9=""Dolar"",'Original Data'!V9*GOOGLEFINANCE(""Currency:USDEUR""), IF($D9=""Franco Suíço"",'Original Data'!V9*GOOGLEFINANCE(""Currency:CHFEUR""), IF($D9=""Libra Esterlina"", 'Orig"&"inal Data'!V9*GOOGLEFINANCE(""Currency:GBPEUR""), IF($D9=""Iene"",'Original Data'!V9*GOOGLEFINANCE(""Currency:JPYEUR""), IF($D9=""HKD"",'Original Data'!V9*GOOGLEFINANCE(""Currency:HKDEUR""), IF($D9=""KRW"",'Original Data'!V9*GOOGLEFINANCE(""Currency:KRWEU"&"R""),""""))))))))"),8.56508) -> 8.56508 | W9: No Response | X9: No Response | Y9: - | Z9: - | AA9: No Response | AB9: No Response | AC9: 34 | AD9: 7.2 | AE9: 18.5 | AF9: 8.6 | AG9: 4
