Workbook

Sheet Original Data
A1: Empresa | B1: BLOOOMBERG TICKER | C1: ISiN Code | D1: Moeda Antiga | E1: Glassdoor | H1: Comparably | M1: Google Finance | R1: Pacto Global
E2: Geral | F2: Cultura e valores | G2: Alta liderança | H2: Culture Score | I2: eNPS | J2: CEO | K2: Managers | L2: Preço Ação Primeira Abertura [EUR] | M2: Ano do Preço Ação Primeira Abertura | N2: Valor da ação há 5 anos [EUR] | O2: Preço Ação Último Fechamento [EUR] | P2: Receita 2021 [EUR] | Q2: EBTIDA 2021 [EUR] | R2: Faz parte do Pacto? Sim ou Não | S2: Quantos engagements faz parte?
A4: BMW AG | B4: BMW GY Equity | C4: DE0005190003 | D4: Euro | E4: 4.2 | F4: 3.9 | G4: 3.7 | H4: 4.5 | I4: 31 | J4: 78 | K4: 76 | L4: =IFERROR(__xludf.DUMMYFUNCTION("IF($D4=""Euro"",'Data in Local Currency'!E4, IF($D4=""Dolar"",'Data in Local Currency'!E4*GOOGLEFINANCE(""Currency:USDEUR""), IF($D4=""Franco Suíço"",'Data in Local Currency'!E4*GOOGLEFINANCE(""Currency:CHFEUR""), IF($D4=""Libra Esterlina"", 'Data in Loca"&"l Currency'!E4*GOOGLEFINANCE(""Currency:GBPEUR""), IF($D4=""Iene"",'Data in Local Currency'!E4*GOOGLEFINANCE(""Currency:JPYEUR""), IF($D4=""HKD"",'Data in Local Currency'!E4*GOOGLEFINANCE(""Currency:HKDEUR""), IF($D4=""KRW"",'Data in Local Currency'!E4*GO"&"OGLEFINANCE(""Currency:KRWEUR""),"""")))))))"),14.1) -> 14.1 | M4: ='Data in Local Currency'!F4 -> 1996 | N4: =IFERROR(__xludf.DUMMYFUNCTION("IF($D4=""Euro"",'Data in Local Currency'!G4, IF($D4=""Dolar"",'Data in Local Currency'!G4*GOOGLEFINANCE(""Currency:USDEUR""), IF($D4=""Franco Suíço"",'Data in Local Currency'!G4*GOOGLEFINANCE(""Currency:CHFEUR""), IF($D4=""Libra Esterlina"", 'Data in Loca"&"l Currency'!G4*GOOGLEFINANCE(""Currency:GBPEUR""), IF($D4=""Iene"",'Data in Local Currency'!G4*GOOGLEFINANCE(""Currency:JPYEUR""), IF($D4=""HKD"",'Data in Local Currency'!G4*GOOGLEFINANCE(""Currency:HKDEUR""), IF($D4=""KRW"",'Data in Local Currency'!G4*GO"&"OGLEFINANCE(""Currency:KRWEUR""),"""")))))))"),7.9) -> 7.9 | O4: 76.67 | P4: 111.24 | Q4: 19.94 | R4: Sim | S4: 3
A5: WALT DISNEY CO | B5: DIS US Equity | C5: US2546871060 | D5: Dolar | E5: 4 | F5: 4 | G5: 3.5 | H5: 4 | I5: 19 | J5: 68 | K5: 71 | L5: =IFERROR(__xludf.DUMMYFUNCTION("IF($D5=""Euro"",'Data in Local Currency'!E5, IF($D5=""Dolar"",'Data in Local Currency'!E5*GOOGLEFINANCE(""Currency:USDEUR""), IF($D5=""Franco Suíço"",'Data in Local Currency'!E5*GOOGLEFINANCE(""Currency:CHFEUR""), IF($D5=""Libra Esterlina"", 'Data in Loca"&"l Currency'!E5*GOOGLEFINANCE(""Currency:GBPEUR""), IF($D5=""Iene"",'Data in Local Currency'!E5*GOOGLEFINANCE(""Currency:JPYEUR""), IF($D5=""HKD"",'Data in Local Currency'!E5*GOOGLEFINANCE(""Currency:HKDEUR""), IF($D5=""KRW"",'Data in Local Currency'!E5*GO"&"OGLEFINANCE(""Currency:KRWEUR""),"""")))))))"),1.0945619999999998) -> 1.094562 | M5: ='Data in Local Currency'!F5 -> 1982 | N5: =IFERROR(__xludf.DUMMYFUNCTION("IF($D5=""Euro"",'Data in Local Currency'!G5, IF($D5=""Dolar"",'Data in Local Currency'!G5*GOOGLEFINANCE(""Currency:USDEUR""), IF($D5=""Franco Suíço"",'Data in Local Currency'!G5*GOOGLEFINANCE(""Currency:CHFEUR""), IF($D5=""Libra Esterlina"", 'Data in Loca"&"l Currency'!G5*GOOGLEFINANCE(""Currency:GBPEUR""), IF($D5=""Iene"",'Data in Local Currency'!G5*GOOGLEFINANCE(""Currency:JPYEUR""), IF($D5=""HKD"",'Data in Local Currency'!G5*GOOGLEFINANCE(""Currency:HKDEUR""), IF($D5=""KRW"",'Data in Local Currency'!G5*GO"&"OGLEFINANCE(""Currency:KRWEUR""),"""")))))))"),104.296122) -> 104.29612 | O5: 125.05 | P5: 61.37 | Q5: 8.06 | R5: Não
A6: ACCENTURE PLCA | B6: ACN US Equity | C6: IE00B4BNMY34 | D6: Dolar | E6: 4.2 | F6: 4.4 | G6: 3.9 | H6: 4.7 | I6: 36 | J6: 85 | K6: 79 | L6: =IFERROR(__xludf.DUMMYFUNCTION("IF($D6=""Euro"",'Data in Local Currency'!E6, IF($D6=""Dolar"",'Data in Local Currency'!E6*GOOGLEFINANCE(""Currency:USDEUR""), IF($D6=""Franco Suíço"",'Data in Local Currency'!E6*GOOGLEFINANCE(""Currency:CHFEUR""), IF($D6=""Libra Esterlina"", 'Data in Loca"&"l Currency'!E6*GOOGLEFINANCE(""Currency:GBPEUR""), IF($D6=""Iene"",'Data in Local Currency'!E6*GOOGLEFINANCE(""Currency:JPYEUR""), IF($D6=""HKD"",'Data in Local Currency'!E6*GOOGLEFINANCE(""Currency:HKDEUR""), IF($D6=""KRW"",'Data in Local Currency'!E6*GO"&"OGLEFINANCE(""Currency:KRWEUR""),"""")))))))"),16.841537999999996) -> 16.841538 | M6: ='Data in Local Currency'!F6 -> 1998 | N6: =IFERROR(__xludf.DUMMYFUNCTION("IF($D6=""Euro"",'Data in Local Currency'!G6, IF($D6=""Dolar"",'Data in Local Currency'!G6*GOOGLEFINANCE(""Currency:USDEUR""), IF($D6=""Franco Suíço"",'Data in Local Currency'!G6*GOOGLEFINANCE(""Currency:CHFEUR""), IF($D6=""Libra Esterlina"", 'Data in Loca"&"l Currency'!G6*GOOGLEFINANCE(""Currency:GBPEUR""), IF($D6=""Iene"",'Data in Local Currency'!G6*GOOGLEFINANCE(""Currency:JPYEUR""), IF($D6=""HKD"",'Data in Local Currency'!G6*GOOGLEFINANCE(""Currency:HKDEUR""), IF($D6=""KRW"",'Data in Local Currency'!G6*GO"&"OGLEFINANCE(""Currency:KRWEUR""),"""")))))))"),110.26562399999999) -> 110.26562 | O6: 292.78 | P6: 46.02 | Q6: 8.76 | R6: Não
A7: MCDONALDS CORP | B7: MCD US Equity | C7: US5801351017 | D7: Dolar | E7: 3.5 | F7: 3.2 | G7: 3.2 | H7: 3.3 | I7: 13 | J7: 65 | K7: 64 | L7: =IFERROR(__xludf.DUMMYFUNCTION("IF($D7=""Euro"",'Data in Local Currency'!E7, IF($D7=""Dolar"",'Data in Local Currency'!E7*GOOGLEFINANCE(""Currency:USDEUR""), IF($D7=""Franco Suíço"",'Data in Local Currency'!E7*GOOGLEFINANCE(""Currency:CHFEUR""), IF($D7=""Libra Esterlina"", 'Data in Loca"&"l Currency'!E7*GOOGLEFINANCE(""Currency:GBPEUR""), IF($D7=""Iene"",'Data in Local Currency'!E7*GOOGLEFINANCE(""Currency:JPYEUR""), IF($D7=""HKD"",'Data in Local Currency'!E7*GOOGLEFINANCE(""Currency:HKDEUR""), IF($D7=""KRW"",'Data in Local Currency'!E7*GO"&"OGLEFINANCE(""Currency:KRWEUR""),"""")))))))"),0.745038) -> 0.745038 | M7: ='Data in Local Currency'!F7 -> 1982 | N7: =IFERROR(__xludf.DUMMYFUNCTION("IF($D7=""Euro"",'Data in Local Currency'!G7, IF($D7=""Dolar"",'Data in Local Currency'!G7*GOOGLEFINANCE(""Currency:USDEUR""), IF($D7=""Franco Suíço"",'Data in Local Currency'!G7*GOOGLEFINANCE(""Currency:CHFEUR""), IF($D7=""Libra Esterlina"", 'Data in Loca"&"l Currency'!G7*GOOGLEFINANCE(""Currency:GBPEUR""), IF($D7=""Iene"",'Data in Local Currency'!G7*GOOGLEFINANCE(""Currency:JPYEUR""), IF($D7=""HKD"",'Data in Local Currency'!G7*GOOGLEFINANCE(""Currency:HKDEUR""), IF($D7=""KRW"",'Data in Local Currency'!G7*GO"&"OGLEFINANCE(""Currency:KRWEUR""),"""")))))))"),119.21527800000001) -> 119.21528 | O7: 212.28 | P7: 21.15 | Q7: 10.6 | R7: Não
A8: HYUNDAI MOTOGDR | B8: HYUD LI Equity | C8: USY384721251 | D8: Dolar | E8: 3.8 | F8: 3.4 | G8: 3.2 | H8: N/A | I8: N/A | J8: N/A | K8: N/A | L8: =IFERROR(__xludf.DUMMYFUNCTION("IF($D8=""Euro"",'Data in Local Currency'!E8, IF($D8=""Dolar"",'Data in Local Currency'!E8*GOOGLEFINANCE(""Currency:USDEUR""), IF($D8=""Franco Suíço"",'Data in Local Currency'!E8*GOOGLEFINANCE(""Currency:CHFEUR""), IF($D8=""Libra Esterlina"", 'Data in Loca"&"l Currency'!E8*GOOGLEFINANCE(""Currency:GBPEUR""), IF($D8=""Iene"",'Data in Local Currency'!E8*GOOGLEFINANCE(""Currency:JPYEUR""), IF($D8=""HKD"",'Data in Local Currency'!E8*GOOGLEFINANCE(""Currency:HKDEUR""), IF($D8=""KRW"",'Data in Local Currency'!E8*GO"&"OGLEFINANCE(""Currency:KRWEUR""),"""")))))))"),2.94336) -> 2.94336 | M8: ='Data in Local Currency'!F8 -> 2001 | N8: =IFERROR(__xludf.DUMMYFUNCTION("IF($D8=""Euro"",'Data in Local Currency'!G8, IF($D8=""Dolar"",'Data in Local Currency'!G8*GOOGLEFINANCE(""Currency:USDEUR""), IF($D8=""Franco Suíço"",'Data in Local Currency'!G8*GOOGLEFINANCE(""Currency:CHFEUR""), IF($D8=""Libra Esterlina"", 'Data in Loca"&"l Currency'!G8*GOOGLEFINANCE(""Currency:GBPEUR""), IF($D8=""Iene"",'Data in Local Currency'!G8*GOOGLEFINANCE(""Currency:JPYEUR""), IF($D8=""HKD"",'Data in Local Currency'!G8*GOOGLEFINANCE(""Currency:HKDEUR""), IF($D8=""KRW"",'Data in Local Currency'!G8*GO"&"OGLEFINANCE(""Currency:KRWEUR""),"""")))))))"),37.02195) -> 37.02195 | O8: 30.7609 | P8: 87.39 | Q8: 8.5 | R8: Sim | S8: 0
A9: CATERPILLAR INC | B9: CAT US Equity | C9: US1491231015 | D9: Dolar | E9: 4 | F9: 3.9 | G9: 3.5 | H9: 2.9 | I9: 4 | J9: 61 | K9: 64 | L9: =IFERROR(__xludf.DUMMYFUNCTION("IF($D9=""Euro"",'Data in Local Currency'!E9, IF($D9=""Dolar"",'Data in Local Currency'!E9*GOOGLEFINANCE(""Currency:USDEUR""), IF($D9=""Franco Suíço"",'Data in Local Currency'!E9*GOOGLEFINANCE(""Currency:CHFEUR""), IF($D9=""Libra Esterlina"", 'Data in Loca"&"l Currency'!E9*GOOGLEFINANCE(""Currency:GBPEUR""), IF($D9=""Iene"",'Data in Local Currency'!E9*GOOGLEFINANCE(""Currency:JPYEUR""), IF($D9=""HKD"",'Data in Local Currency'!E9*GOOGLEFINANCE(""Currency:HKDEUR""), IF($D9=""KRW"",'Data in Local Currency'!E9*GO"&"OGLEFINANCE(""Currency:KRWEUR""),"""")))))))"),5.546394) -> 5.546394 | M9: ='Data in Local Currency'!F9 -> 1982 | N9: =IFERROR(__xludf.DUMMYFUNCTION("IF($D9=""Euro"",'Data in Local Currency'!G9, IF($D9=""Dolar"",'Data in Local Currency'!G9*GOOGLEFINANCE(""Currency:USDEUR""), IF($D9=""Franco Suíço"",'Data in Local Currency'!G9*GOOGLEFINANCE(""Currency:CHFEUR""), IF($D9=""Libra Esterlina"", 'Data in Loca"&"l Currency'!G9*GOOGLEFINANCE(""Currency:GBPEUR""), IF($D9=""Iene"",'Data in Local Currency'!G9*GOOGLEFINANCE(""Currency:JPYEUR""), IF($D9=""HKD"",'Data in Local Currency'!G9*GOOGLEFINANCE(""Currency:HKDEUR""), IF($D9=""KRW"",'Data in Local Currency'!G9*GO"&"OGLEFINANCE(""Currency:KRWEUR""),"""")))))))"),85.320648) -> 85.320648 | O9: 201.77 | P9: 46.43 | Q9: 8.49 | R9: Não
A10: ALIBABA GRPADR | B10: BABA US Equity | C10: US01609W1027 | D10: Dolar | E10: 4 | F10: 3.6 | G10: 3.6 | H10: 4.3 | I10: 33 | J10: 80 | K10: 57 | L10: =IFERROR(__xludf.DUMMYFUNCTION("IF($D10=""Euro"",'Data in Local Currency'!E10, IF($D10=""Dolar"",'Data in Local Currency'!E10*GOOGLEFINANCE(""Currency:USDEUR""), IF($D10=""Franco Suíço"",'Data in Local Currency'!E10*GOOGLEFINANCE(""Currency:CHFEUR""), IF($D10=""Libra Esterlina"", 'Data "&"in Local Currency'!E10*GOOGLEFINANCE(""Currency:GBPEUR""), IF($D10=""Iene"",'Data in Local Currency'!E10*GOOGLEFINANCE(""Currency:JPYEUR""), IF($D10=""HKD"",'Data in Local Currency'!E10*GOOGLEFINANCE(""Currency:HKDEUR""), IF($D10=""KRW"",'Data in Local Cu"&"rrency'!E10*GOOGLEFINANCE(""Currency:KRWEUR""),"""")))))))"),78.99242399999999) -> 78.992424 | M10: ='Data in Local Currency'!F10 -> 2014 | N10: =IFERROR(__xludf.DUMMYFUNCTION("IF($D10=""Euro"",'Data in Local Currency'!G10, IF($D10=""Dolar"",'Data in Local Currency'!G10*GOOGLEFINANCE(""Currency:USDEUR""), IF($D10=""Franco Suíço"",'Data in Local Currency'!G10*GOOGLEFINANCE(""Currency:CHFEUR""), IF($D10=""Libra Esterlina"", 'Data "&"in Local Currency'!G10*GOOGLEFINANCE(""Currency:GBPEUR""), IF($D10=""Iene"",'Data in Local Currency'!G10*GOOGLEFINANCE(""Currency:JPYEUR""), IF($D10=""HKD"",'Data in Local Currency'!G10*GOOGLEFINANCE(""Currency:HKDEUR""), IF($D10=""KRW"",'Data in Local Cu"&"rrency'!G10*GOOGLEFINANCE(""Currency:KRWEUR""),"""")))))))"),99.18203399999999) -> 99.182034 | O10: 93.39 | P10: 102.51 | Q10: 28.13 | R10: Sim | S10: 2
A11: STARBUCKS CORP | B11: SBUX US Equity | C11: US8552441094 | D11: Dolar | E11: 3.8 | F11: 3.8 | G11: 3.3 | H11: 4.5 | I11: 15 | J11: 71 | K11: 72 | L11: =IFERROR(__xludf.DUMMYFUNCTION("IF($D11=""Euro"",'Data in Local Currency'!E11, IF($D11=""Dolar"",'Data in Local Currency'!E11*GOOGLEFINANCE(""Currency:USDEUR""), IF($D11=""Franco Suíço"",'Data in Local Currency'!E11*GOOGLEFINANCE(""Currency:CHFEUR""), IF($D11=""Libra Esterlina"", 'Data "&"in Local Currency'!E11*GOOGLEFINANCE(""Currency:GBPEUR""), IF($D11=""Iene"",'Data in Local Currency'!E11*GOOGLEFINANCE(""Currency:JPYEUR""), IF($D11=""HKD"",'Data in Local Currency'!E11*GOOGLEFINANCE(""Currency:HKDEUR""), IF($D11=""KRW"",'Data in Local Cu"&"rrency'!E11*GOOGLEFINANCE(""Currency:KRWEUR""),"""")))))))"),0.294336) -> 0.294336 | M11: ='Data in Local Currency'!F11 -> 1992 | N11: =IFERROR(__xludf.DUMMYFUNCTION("IF($D11=""Euro"",'Data in Local Currency'!G11, IF($D11=""Dolar"",'Data in Local Currency'!G11*GOOGLEFINANCE(""Currency:USDEUR""), IF($D11=""Franco Suíço"",'Data in Local Currency'!G11*GOOGLEFINANCE(""Currency:CHFEUR""), IF($D11=""Libra Esterlina"", 'Data "&"in Local Currency'!G11*GOOGLEFINANCE(""Currency:GBPEUR""), IF($D11=""Iene"",'Data in Local Currency'!G11*GOOGLEFINANCE(""Currency:JPYEUR""), IF($D11=""HKD"",'Data in Local Currency'!G11*GOOGLEFINANCE(""Currency:HKDEUR""), IF($D11=""KRW"",'Data in Local Cu"&"rrency'!G11*GOOGLEFINANCE(""Currency:KRWEUR""),"""")))))))"),55.243187999999996) -> 55.243188 | O11: 78.35 | P11: 26.47 | Q11: 6.78 | R11: Sim | S11: 4
A12: VIDRALA | B12: VID SM Equity | C12: ES0183746314 | D12: Euro | E12: 3.4 | F12: 3.4 | G12: 2.7 | H12: N/A | I12: N/A | J12: N/A | K12: N/A | L12: =IFERROR(__xludf.DUMMYFUNCTION("IF($D12=""Euro"",'Data in Local Currency'!E12, IF($D12=""Dolar"",'Data in Local Currency'!E12*GOOGLEFINANCE(""Currency:USDEUR""), IF($D12=""Franco Suíço"",'Data in Local Currency'!E12*GOOGLEFINANCE(""Currency:CHFEUR""), IF($D12=""Libra Esterlina"", 'Data "&"in Local Currency'!E12*GOOGLEFINANCE(""Currency:GBPEUR""), IF($D12=""Iene"",'Data in Local Currency'!E12*GOOGLEFINANCE(""Currency:JPYEUR""), IF($D12=""HKD"",'Data in Local Currency'!E12*GOOGLEFINANCE(""Currency:HKDEUR""), IF($D12=""KRW"",'Data in Local Cu"&"rrency'!E12*GOOGLEFINANCE(""Currency:KRWEUR""),"""")))))))"),4.6) -> 4.6 | M12: ='Data in Local Currency'!F12 -> 2000 | N12: =IFERROR(__xludf.DUMMYFUNCTION("IF($D12=""Euro"",'Data in Local Currency'!G12, IF($D12=""Dolar"",'Data in Local Currency'!G12*GOOGLEFINANCE(""Currency:USDEUR""), IF($D12=""Franco Suíço"",'Data in Local Currency'!G12*GOOGLEFINANCE(""Currency:CHFEUR""), IF($D12=""Libra Esterlina"", 'Data "&"in Local Currency'!G12*GOOGLEFINANCE(""Currency:GBPEUR""), IF($D12=""Iene"",'Data in Local Currency'!G12*GOOGLEFINANCE(""Currency:JPYEUR""), IF($D12=""HKD"",'Data in Local Currency'!G12*GOOGLEFINANCE(""Currency:HKDEUR""), IF($D12=""KRW"",'Data in Local Cu"&"rrency'!G12*GOOGLEFINANCE(""Currency:KRWEUR""),"""")))))))"),44.34) -> 44.34 | O12: 64.8 | P12: 1.08 | Q12: 0.23 | R12: Não
A13: ROYAL DUTCH SHA | B13: RDSA NA Equity | C13: GB00B03MLX29 | D13: Euro | E13: 4.1 | F13: 4.1 | G13: 3.6 | H13: 3.7 | I13: 19 | J13: 73 | K13: 67 | L13: =IFERROR(__xludf.DUMMYFUNCTION("IF($D13=""Euro"",'Data in Local Currency'!E13, IF($D13=""Dolar"",'Data in Local Currency'!E13*GOOGLEFINANCE(""Currency:USDEUR""), IF($D13=""Franco Suíço"",'Data in Local Currency'!E13*GOOGLEFINANCE(""Currency:CHFEUR""), IF($D13=""Libra Esterlina"", 'Data "&"in Local Currency'!E13*GOOGLEFINANCE(""Currency:GBPEUR""), IF($D13=""Iene"",'Data in Local Currency'!E13*GOOGLEFINANCE(""Currency:JPYEUR""), IF($D13=""HKD"",'Data in Local Currency'!E13*GOOGLEFINANCE(""Currency:HKDEUR""), IF($D13=""KRW"",'Data in Local Cu"&"rrency'!E13*GOOGLEFINANCE(""Currency:KRWEUR""),"""")))))))"),26.44) -> 26.44 | M13: ='Data in Local Currency'!F13 -> 2005 | N13: =IFERROR(__xludf.DUMMYFUNCTION("IF($D13=""Euro"",'Data in Local Currency'!G13, IF($D13=""Dolar"",'Data in Local Currency'!G13*GOOGLEFINANCE(""Currency:USDEUR""), IF($D13=""Franco Suíço"",'Data in Local Currency'!G13*GOOGLEFINANCE(""Currency:CHFEUR""), IF($D13=""Libra Esterlina"", 'Data "&"in Local Currency'!G13*GOOGLEFINANCE(""Currency:GBPEUR""), IF($D13=""Iene"",'Data in Local Currency'!G13*GOOGLEFINANCE(""Currency:JPYEUR""), IF($D13=""HKD"",'Data in Local Currency'!G13*GOOGLEFINANCE(""Currency:HKDEUR""), IF($D13=""KRW"",'Data in Local Cu"&"rrency'!G13*GOOGLEFINANCE(""Currency:KRWEUR""),"""")))))))"),23.88) -> 23.88 | O13: 24.14 | P13: 238.15 | Q13: 28.9 | R13: Sim | S13: 2
A14: HOLCIM LTD | B14: HOLN SW Equity | C14: CH0012214059 | D14: Franco Suíço | E14: 3.7 | F14: 3.4 | G14: 3.1 | H14: 4.1 | I14: 25 | J14: 63 | K14: 69 | L14: =IFERROR(__xludf.DUMMYFUNCTION("IF($D14=""Euro"",'Data in Local Currency'!E14, IF($D14=""Dolar"",'Data in Local Currency'!E14*GOOGLEFINANCE(""Currency:USDEUR""), IF($D14=""Franco Suíço"",'Data in Local Currency'!E14*GOOGLEFINANCE(""Currency:CHFEUR""), IF($D14=""Libra Esterlina"", 'Data "&"in Local Currency'!E14*GOOGLEFINANCE(""Currency:GBPEUR""), IF($D14=""Iene"",'Data in Local Currency'!E14*GOOGLEFINANCE(""Currency:JPYEUR""), IF($D14=""HKD"",'Data in Local Currency'!E14*GOOGLEFINANCE(""Currency:HKDEUR""), IF($D14=""KRW"",'Data in Local Cu"&"rrency'!E14*GOOGLEFINANCE(""Currency:KRWEUR""),"""")))))))"),29.446945343999996) -> 29.446945 | M14: ='Data in Local Currency'!F14 -> 2001 | N14: =IFERROR(__xludf.DUMMYFUNCTION("IF($D14=""Euro"",'Data in Local Currency'!G14, IF($D14=""Dolar"",'Data in Local Currency'!G14*GOOGLEFINANCE(""Currency:USDEUR""), IF($D14=""Franco Suíço"",'Data in Local Currency'!G14*GOOGLEFINANCE(""Currency:CHFEUR""), IF($D14=""Libra Esterlina"", 'Data "&"in Local Currency'!G14*GOOGLEFINANCE(""Currency:GBPEUR""), IF($D14=""Iene"",'Data in Local Currency'!G14*GOOGLEFINANCE(""Currency:JPYEUR""), IF($D14=""HKD"",'Data in Local Currency'!G14*GOOGLEFINANCE(""Currency:HKDEUR""), IF($D14=""KRW"",'Data in Local Cu"&"rrency'!G14*GOOGLEFINANCE(""Currency:KRWEUR""),"""")))))))"),55.52683775999999) -> 55.526838 | O14: 44.73 | P14: 26.12 | Q14: 6.25 | R14: Sim | S14: 8
A15: MICHELIN | B15: ML FP Equity | C15: FR0000121261 | D15: Euro | E15: 4.1 | F15: 4.2 | G15: 3.8 | H15: 4.5 | I15: 35 | J15: 78 | K15: 72 | L15: =IFERROR(__xludf.DUMMYFUNCTION("IF($D15=""Euro"",'Data in Local Currency'!E15, IF($D15=""Dolar"",'Data in Local Currency'!E15*GOOGLEFINANCE(""Currency:USDEUR""), IF($D15=""Franco Suíço"",'Data in Local Currency'!E15*GOOGLEFINANCE(""Currency:CHFEUR""), IF($D15=""Libra Esterlina"", 'Data "&"in Local Currency'!E15*GOOGLEFINANCE(""Currency:GBPEUR""), IF($D15=""Iene"",'Data in Local Currency'!E15*GOOGLEFINANCE(""Currency:JPYEUR""), IF($D15=""HKD"",'Data in Local Currency'!E15*GOOGLEFINANCE(""Currency:HKDEUR""), IF($D15=""KRW"",'Data in Local Cu"&"rrency'!E15*GOOGLEFINANCE(""Currency:KRWEUR""),"""")))))))"),31.34) -> 31.34 | M15: ='Data in Local Currency'!F15 -> 2000 | N15: =IFERROR(__xludf.DUMMYFUNCTION("IF($D15=""Euro"",'Data in Local Currency'!G15, IF($D15=""Dolar"",'Data in Local Currency'!G15*GOOGLEFINANCE(""Currency:USDEUR""), IF($D15=""Franco Suíço"",'Data in Local Currency'!G15*GOOGLEFINANCE(""Currency:CHFEUR""), IF($D15=""Libra Esterlina"", 'Data "&"in Local Currency'!G15*GOOGLEFINANCE(""Currency:GBPEUR""), IF($D15=""Iene"",'Data in Local Currency'!G15*GOOGLEFINANCE(""Currency:JPYEUR""), IF($D15=""HKD"",'Data in Local Currency'!G15*GOOGLEFINANCE(""Currency:HKDEUR""), IF($D15=""KRW"",'Data in Local Cu"&"rrency'!G15*GOOGLEFINANCE(""Currency:KRWEUR""),"""")))))))"),119.95) -> 119.95 | O15: 123.25 | P15: 23.8 | R15: Sim | S15: 3
A16: RYANAIR HLDGS | B16: RYA ID Equity | C16: IE00BYTBXV33 | D16: Euro | E16: 3.3 | F16: 2.9 | G16: 2.7 | H16: 2.6 | I16: 75 | J16: 25 | K16: 38 | L16: =IFERROR(__xludf.DUMMYFUNCTION("IF($D16=""Euro"",'Data in Local Currency'!E16, IF($D16=""Dolar"",'Data in Local Currency'!E16*GOOGLEFINANCE(""Currency:USDEUR""), IF($D16=""Franco Suíço"",'Data in Local Currency'!E16*GOOGLEFINANCE(""Currency:CHFEUR""), IF($D16=""Libra Esterlina"", 'Data "&"in Local Currency'!E16*GOOGLEFINANCE(""Currency:GBPEUR""), IF($D16=""Iene"",'Data in Local Currency'!E16*GOOGLEFINANCE(""Currency:JPYEUR""), IF($D16=""HKD"",'Data in Local Currency'!E16*GOOGLEFINANCE(""Currency:HKDEUR""), IF($D16=""KRW"",'Data in Local Cu"&"rrency'!E16*GOOGLEFINANCE(""Currency:KRWEUR""),"""")))))))"),1.97) -> 1.97 | M16: ='Data in Local Currency'!F16 -> 2002 | N16: =IFERROR(__xludf.DUMMYFUNCTION("IF($D16=""Euro"",'Data in Local Currency'!G16, IF($D16=""Dolar"",'Data in Local Currency'!G16*GOOGLEFINANCE(""Currency:USDEUR""), IF($D16=""Franco Suíço"",'Data in Local Currency'!G16*GOOGLEFINANCE(""Currency:CHFEUR""), IF($D16=""Libra Esterlina"", 'Data "&"in Local Currency'!G16*GOOGLEFINANCE(""Currency:GBPEUR""), IF($D16=""Iene"",'Data in Local Currency'!G16*GOOGLEFINANCE(""Currency:JPYEUR""), IF($D16=""HKD"",'Data in Local Currency'!G16*GOOGLEFINANCE(""Currency:HKDEUR""), IF($D16=""KRW"",'Data in Local Cu"&"rrency'!G16*GOOGLEFINANCE(""Currency:KRWEUR""),"""")))))))"),15.95) -> 15.95 | O16: 13.7 | P16: 1.64 | R16: Sim | S16: 0
A17: TRIGANO SA | B17: TRI FP Equity | C17: FR0005691656 | D17: Euro | E17: 3.4 | F17: 2.4 | G17: 2.4 | H17: N/A | I17: N/A | J17: N/A | K17: N/A | L17: =IFERROR(__xludf.DUMMYFUNCTION("IF($D17=""Euro"",'Data in Local Currency'!E17, IF($D17=""Dolar"",'Data in Local Currency'!E17*GOOGLEFINANCE(""Currency:USDEUR""), IF($D17=""Franco Suíço"",'Data in Local Currency'!E17*GOOGLEFINANCE(""Currency:CHFEUR""), IF($D17=""Libra Esterlina"", 'Data "&"in Local Currency'!E17*GOOGLEFINANCE(""Currency:GBPEUR""), IF($D17=""Iene"",'Data in Local Currency'!E17*GOOGLEFINANCE(""Currency:JPYEUR""), IF($D17=""HKD"",'Data in Local Currency'!E17*GOOGLEFINANCE(""Currency:HKDEUR""), IF($D17=""KRW"",'Data in Local Cu"&"rrency'!E17*GOOGLEFINANCE(""Currency:KRWEUR""),"""")))))))"),2.9) -> 2.9 | M17: ='Data in Local Currency'!F17 -> 1998 | N17: =IFERROR(__xludf.DUMMYFUNCTION("IF($D17=""Euro"",'Data in Local Currency'!G17, IF($D17=""Dolar"",'Data in Local Currency'!G17*GOOGLEFINANCE(""Currency:USDEUR""), IF($D17=""Franco Suíço"",'Data in Local Currency'!G17*GOOGLEFINANCE(""Currency:CHFEUR""), IF($D17=""Libra Esterlina"", 'Data "&"in Local Currency'!G17*GOOGLEFINANCE(""Currency:GBPEUR""), IF($D17=""Iene"",'Data in Local Currency'!G17*GOOGLEFINANCE(""Currency:JPYEUR""), IF($D17=""HKD"",'Data in Local Currency'!G17*GOOGLEFINANCE(""Currency:HKDEUR""), IF($D17=""KRW"",'Data in Local Cu"&"rrency'!G17*GOOGLEFINANCE(""Currency:KRWEUR""),"""")))))))"),97.05) -> 97.05 | O17: 139.7 | P17: 2.93 | Q17: 0.42 | R17: Não
A18: BENETEAU | B18: BEN FP Equity | C18: FR0000035164 | D18: Euro | E18: 3.7 | F18: 3.4 | G18: 3 | H18: N/A | I18: N/A | J18: N/A | K18: N/A | L18: =IFERROR(__xludf.DUMMYFUNCTION("IF($D18=""Euro"",'Data in Local Currency'!E18, IF($D18=""Dolar"",'Data in Local Currency'!E18*GOOGLEFINANCE(""Currency:USDEUR""), IF($D18=""Franco Suíço"",'Data in Local Currency'!E18*GOOGLEFINANCE(""Currency:CHFEUR""), IF($D18=""Libra Esterlina"", 'Data "&"in Local Currency'!E18*GOOGLEFINANCE(""Currency:GBPEUR""), IF($D18=""Iene"",'Data in Local Currency'!E18*GOOGLEFINANCE(""Currency:JPYEUR""), IF($D18=""HKD"",'Data in Local Currency'!E18*GOOGLEFINANCE(""Currency:HKDEUR""), IF($D18=""KRW"",'Data in Local Cu"&"rrency'!E18*GOOGLEFINANCE(""Currency:KRWEUR""),"""")))))))"),0.18) -> 0.18 | M18: ='Data in Local Currency'!F18 -> 1997 | N18: =IFERROR(__xludf.DUMMYFUNCTION("IF($D18=""Euro"",'Data in Local Currency'!G18, IF($D18=""Dolar"",'Data in Local Currency'!G18*GOOGLEFINANCE(""Currency:USDEUR""), IF($D18=""Franco Suíço"",'Data in Local Currency'!G18*GOOGLEFINANCE(""Currency:CHFEUR""), IF($D18=""Libra Esterlina"", 'Data "&"in Local Currency'!G18*GOOGLEFINANCE(""Currency:GBPEUR""), IF($D18=""Iene"",'Data in Local Currency'!G18*GOOGLEFINANCE(""Currency:JPYEUR""), IF($D18=""HKD"",'Data in Local Currency'!G18*GOOGLEFINANCE(""Currency:HKDEUR""), IF($D18=""KRW"",'Data in Local Cu"&"rrency'!G18*GOOGLEFINANCE(""Currency:KRWEUR""),"""")))))))"),13.02) -> 13.02 | O18: 14.16 | P18: 1.23 | R18: Sim | S18: 0
A19: SAINT GOBAIN | B19: SGO FP Equity | C19: FR0000125007 | D19: Euro | E19: 4.1 | F19: 4.1 | G19: 3.6 | H19: N/A | I19: N/A | J19: N/A | K19: N/A | L19: =IFERROR(__xludf.DUMMYFUNCTION("IF($D19=""Euro"",'Data in Local Currency'!E19, IF($D19=""Dolar"",'Data in Local Currency'!E19*GOOGLEFINANCE(""Currency:USDEUR""), IF($D19=""Franco Suíço"",'Data in Local Currency'!E19*GOOGLEFINANCE(""Currency:CHFEUR""), IF($D19=""Libra Esterlina"", 'Data "&"in Local Currency'!E19*GOOGLEFINANCE(""Currency:GBPEUR""), IF($D19=""Iene"",'Data in Local Currency'!E19*GOOGLEFINANCE(""Currency:JPYEUR""), IF($D19=""HKD"",'Data in Local Currency'!E19*GOOGLEFINANCE(""Currency:HKDEUR""), IF($D19=""KRW"",'Data in Local Cu"&"rrency'!E19*GOOGLEFINANCE(""Currency:KRWEUR""),"""")))))))"),36.13) -> 36.13 | M19: ='Data in Local Currency'!F19 -> 2000 | N19: =IFERROR(__xludf.DUMMYFUNCTION("IF($D19=""Euro"",'Data in Local Currency'!G19, IF($D19=""Dolar"",'Data in Local Currency'!G19*GOOGLEFINANCE(""Currency:USDEUR""), IF($D19=""Franco Suíço"",'Data in Local Currency'!G19*GOOGLEFINANCE(""Currency:CHFEUR""), IF($D19=""Libra Esterlina"", 'Data "&"in Local Currency'!G19*GOOGLEFINANCE(""Currency:GBPEUR""), IF($D19=""Iene"",'Data in Local Currency'!G19*GOOGLEFINANCE(""Currency:JPYEUR""), IF($D19=""HKD"",'Data in Local Currency'!G19*GOOGLEFINANCE(""Currency:HKDEUR""), IF($D19=""KRW"",'Data in Local Cu"&"rrency'!G19*GOOGLEFINANCE(""Currency:KRWEUR""),"""")))))))"),49.55) -> 49.55 | O19: 57.88 | P19: 44.16 | Q19: 6.44 | R19: Sim | S19: 6
A20: BEKAERT NV | B20: BEKB BB Equity | C20: BE0974258874 | D20: Euro | E20: 4.1 | F20: 3.9 | G20: 3.5 | H20: 3 | I20: 75 | J20: 58 | K20: 60 | L20: =IFERROR(__xludf.DUMMYFUNCTION("IF($D20=""Euro"",'Data in Local Currency'!E20, IF($D20=""Dolar"",'Data in Local Currency'!E20*GOOGLEFINANCE(""Currency:USDEUR""), IF($D20=""Franco Suíço"",'Data in Local Currency'!E20*GOOGLEFINANCE(""Currency:CHFEUR""), IF($D20=""Libra Esterlina"", 'Data "&"in Local Currency'!E20*GOOGLEFINANCE(""Currency:GBPEUR""), IF($D20=""Iene"",'Data in Local Currency'!E20*GOOGLEFINANCE(""Currency:JPYEUR""), IF($D20=""HKD"",'Data in Local Currency'!E20*GOOGLEFINANCE(""Currency:HKDEUR""), IF($D20=""KRW"",'Data in Local Cu"&"rrency'!E20*GOOGLEFINANCE(""Currency:KRWEUR""),"""")))))))"),18.17) -> 18.17 | M20: ='Data in Local Currency'!F20 -> 2000 | N20: =IFERROR(__xludf.DUMMYFUNCTION("IF($D20=""Euro"",'Data in Local Currency'!G20, IF($D20=""Dolar"",'Data in Local Currency'!G20*GOOGLEFINANCE(""Currency:USDEUR""), IF($D20=""Franco Suíço"",'Data in Local Currency'!G20*GOOGLEFINANCE(""Currency:CHFEUR""), IF($D20=""Libra Esterlina"", 'Data "&"in Local Currency'!G20*GOOGLEFINANCE(""Currency:GBPEUR""), IF($D20=""Iene"",'Data in Local Currency'!G20*GOOGLEFINANCE(""Currency:JPYEUR""), IF($D20=""HKD"",'Data in Local Currency'!G20*GOOGLEFINANCE(""Currency:HKDEUR""), IF($D20=""KRW"",'Data in Local Cu"&"rrency'!G20*GOOGLEFINANCE(""Currency:KRWEUR""),"""")))))))"),46.22) -> 46.22 | O20: 36.92 | P20: 4.84 | Q20: 0.64 | R20: Não
A21: STABILUS SA | B21: STM GY Equity | C21: LU1066226637 | D21: Euro | E21: 3.9 | F21: 3.6 | G21: 3.4 | H21: N/A | I21: N/A | J21: N/A | K21: N/A | L21: =IFERROR(__xludf.DUMMYFUNCTION("IF($D21=""Euro"",'Data in Local Currency'!E21, IF($D21=""Dolar"",'Data in Local Currency'!E21*GOOGLEFINANCE(""Currency:USDEUR""), IF($D21=""Franco Suíço"",'Data in Local Currency'!E21*GOOGLEFINANCE(""Currency:CHFEUR""), IF($D21=""Libra Esterlina"", 'Data "&"in Local Currency'!E21*GOOGLEFINANCE(""Currency:GBPEUR""), IF($D21=""Iene"",'Data in Local Currency'!E21*GOOGLEFINANCE(""Currency:JPYEUR""), IF($D21=""HKD"",'Data in Local Currency'!E21*GOOGLEFINANCE(""Currency:HKDEUR""), IF($D21=""KRW"",'Data in Local Cu"&"rrency'!E21*GOOGLEFINANCE(""Currency:KRWEUR""),"""")))))))"),23.35) -> 23.35 | M21: ='Data in Local Currency'!F21 -> 2016 | N21: =IFERROR(__xludf.DUMMYFUNCTION("IF($D21=""Euro"",'Data in Local Currency'!G21, IF($D21=""Dolar"",'Data in Local Currency'!G21*GOOGLEFINANCE(""Currency:USDEUR""), IF($D21=""Franco Suíço"",'Data in Local Currency'!G21*GOOGLEFINANCE(""Currency:CHFEUR""), IF($D21=""Libra Esterlina"", 'Data "&"in Local Currency'!G21*GOOGLEFINANCE(""Currency:GBPEUR""), IF($D21=""Iene"",'Data in Local Currency'!G21*GOOGLEFINANCE(""Currency:JPYEUR""), IF($D21=""HKD"",'Data in Local Currency'!G21*GOOGLEFINANCE(""Currency:HKDEUR""), IF($D21=""KRW"",'Data in Local Cu"&"rrency'!G21*GOOGLEFINANCE(""Currency:KRWEUR""),"""")))))))"),66.49) -> 66.49 | O21: 50.35 | P21: 0.94 | Q21: 0.02 | R21: Sim | S21: 0
A22: DECEUNINCK NV | B22: DECB BB Equity | C22: BE0003789063 | D22: Euro | E22: 2.8 | F22: 2.2 | G22: 2.3 | H22: N/A | I22: N/A | J22: N/A | K22: N/A | L22: =IFERROR(__xludf.DUMMYFUNCTION("IF($D22=""Euro"",'Data in Local Currency'!E22, IF($D22=""Dolar"",'Data in Local Currency'!E22*GOOGLEFINANCE(""Currency:USDEUR""), IF($D22=""Franco Suíço"",'Data in Local Currency'!E22*GOOGLEFINANCE(""Currency:CHFEUR""), IF($D22=""Libra Esterlina"", 'Data "&"in Local Currency'!E22*GOOGLEFINANCE(""Currency:GBPEUR""), IF($D22=""Iene"",'Data in Local Currency'!E22*GOOGLEFINANCE(""Currency:JPYEUR""), IF($D22=""HKD"",'Data in Local Currency'!E22*GOOGLEFINANCE(""Currency:HKDEUR""), IF($D22=""KRW"",'Data in Local Cu"&"rrency'!E22*GOOGLEFINANCE(""Currency:KRWEUR""),"""")))))))"),7.01) -> 7.01 | M22: ='Data in Local Currency'!F22 -> 2000 | N22: =IFERROR(__xludf.DUMMYFUNCTION("IF($D22=""Euro"",'Data in Local Currency'!G22, IF($D22=""Dolar"",'Data in Local Currency'!G22*GOOGLEFINANCE(""Currency:USDEUR""), IF($D22=""Franco Suíço"",'Data in Local Currency'!G22*GOOGLEFINANCE(""Currency:CHFEUR""), IF($D22=""Libra Esterlina"", 'Data "&"in Local Currency'!G22*GOOGLEFINANCE(""Currency:GBPEUR""), IF($D22=""Iene"",'Data in Local Currency'!G22*GOOGLEFINANCE(""Currency:JPYEUR""), IF($D22=""HKD"",'Data in Local Currency'!G22*GOOGLEFINANCE(""Currency:HKDEUR""), IF($D22=""KRW"",'Data in Local Cu"&"rrency'!G22*GOOGLEFINANCE(""Currency:KRWEUR""),"""")))))))"),2.78) -> 2.78 | O22: 2.83 | P22: 0.84 | Q22: 0.09 | R22: Sim | S22: 2
A23: MUNCHENER RUER | B23: MUV2 GY Equity | C23: DE0008430026 | D23: Euro | E23: 4.4 | F23: 4.1 | G23: 3.9 | H23: 2.8 | I23: 17 | J23: 78 | K23: 50 | L23: =IFERROR(__xludf.DUMMYFUNCTION("IF($D23=""Euro"",'Data in Local Currency'!E23, IF($D23=""Dolar"",'Data in Local Currency'!E23*GOOGLEFINANCE(""Currency:USDEUR""), IF($D23=""Franco Suíço"",'Data in Local Currency'!E23*GOOGLEFINANCE(""Currency:CHFEUR""), IF($D23=""Libra Esterlina"", 'Data "&"in Local Currency'!E23*GOOGLEFINANCE(""Currency:GBPEUR""), IF($D23=""Iene"",'Data in Local Currency'!E23*GOOGLEFINANCE(""Currency:JPYEUR""), IF($D23=""HKD"",'Data in Local Currency'!E23*GOOGLEFINANCE(""Currency:HKDEUR""), IF($D23=""KRW"",'Data in Local Cu"&"rrency'!E23*GOOGLEFINANCE(""Currency:KRWEUR""),"""")))))))"),216.89) -> 216.89 | M23: ='Data in Local Currency'!F23 -> 1998 | N23: =IFERROR(__xludf.DUMMYFUNCTION("IF($D23=""Euro"",'Data in Local Currency'!G23, IF($D23=""Dolar"",'Data in Local Currency'!G23*GOOGLEFINANCE(""Currency:USDEUR""), IF($D23=""Franco Suíço"",'Data in Local Currency'!G23*GOOGLEFINANCE(""Currency:CHFEUR""), IF($D23=""Libra Esterlina"", 'Data "&"in Local Currency'!G23*GOOGLEFINANCE(""Currency:GBPEUR""), IF($D23=""Iene"",'Data in Local Currency'!G23*GOOGLEFINANCE(""Currency:JPYEUR""), IF($D23=""HKD"",'Data in Local Currency'!G23*GOOGLEFINANCE(""Currency:HKDEUR""), IF($D23=""KRW"",'Data in Local Cu"&"rrency'!G23*GOOGLEFINANCE(""Currency:KRWEUR""),"""")))))))"),175.95) -> 175.95 | O23: 240 | P23: 70.24 | R23: Sim | S23: 0
A24: AENA SME SA | B24: AENA SM Equity | C24: ES0105046009 | D24: Euro | E24: 3.7 | F24: 3.3 | G24: 3.2 | H24: N/A | I24: N/A | J24: N/A | K24: N/A | L24: =IFERROR(__xludf.DUMMYFUNCTION("IF($D24=""Euro"",'Data in Local Currency'!E24, IF($D24=""Dolar"",'Data in Local Currency'!E24*GOOGLEFINANCE(""Currency:USDEUR""), IF($D24=""Franco Suíço"",'Data in Local Currency'!E24*GOOGLEFINANCE(""Currency:CHFEUR""), IF($D24=""Libra Esterlina"", 'Data "&"in Local Currency'!E24*GOOGLEFINANCE(""Currency:GBPEUR""), IF($D24=""Iene"",'Data in Local Currency'!E24*GOOGLEFINANCE(""Currency:JPYEUR""), IF($D24=""HKD"",'Data in Local Currency'!E24*GOOGLEFINANCE(""Currency:HKDEUR""), IF($D24=""KRW"",'Data in Local Cu"&"rrency'!E24*GOOGLEFINANCE(""Currency:KRWEUR""),"""")))))))"),74.0) -> 74 | M24: ='Data in Local Currency'!F24 -> 2015 | N24: =IFERROR(__xludf.DUMMYFUNCTION("IF($D24=""Euro"",'Data in Local Currency'!G24, IF($D24=""Dolar"",'Data in Local Currency'!G24*GOOGLEFINANCE(""Currency:USDEUR""), IF($D24=""Franco Suíço"",'Data in Local Currency'!G24*GOOGLEFINANCE(""Currency:CHFEUR""), IF($D24=""Libra Esterlina"", 'Data "&"in Local Currency'!G24*GOOGLEFINANCE(""Currency:GBPEUR""), IF($D24=""Iene"",'Data in Local Currency'!G24*GOOGLEFINANCE(""Currency:JPYEUR""), IF($D24=""HKD"",'Data in Local Currency'!G24*GOOGLEFINANCE(""Currency:HKDEUR""), IF($D24=""KRW"",'Data in Local Cu"&"rrency'!G24*GOOGLEFINANCE(""Currency:KRWEUR""),"""")))))))"),162.0) -> 162 | O24: 145.15 | P24: 2.32 | Q24: 0.82 | R24: Sim | S24: 0
A25: CORTICEIRA AMORI | B25: COR PL Equity | C25: PTCOR0AE0006 | D25: Euro | E25: 3.5 | F25: 3.9 | G25: 4 | H25: N/A | I25: N/A | J25: N/A | K25: N/A | L25: =IFERROR(__xludf.DUMMYFUNCTION("IF($D25=""Euro"",'Data in Local Currency'!E25, IF($D25=""Dolar"",'Data in Local Currency'!E25*GOOGLEFINANCE(""Currency:USDEUR""), IF($D25=""Franco Suíço"",'Data in Local Currency'!E25*GOOGLEFINANCE(""Currency:CHFEUR""), IF($D25=""Libra Esterlina"", 'Data "&"in Local Currency'!E25*GOOGLEFINANCE(""Currency:GBPEUR""), IF($D25=""Iene"",'Data in Local Currency'!E25*GOOGLEFINANCE(""Currency:JPYEUR""), IF($D25=""HKD"",'Data in Local Currency'!E25*GOOGLEFINANCE(""Currency:HKDEUR""), IF($D25=""KRW"",'Data in Local Cu"&"rrency'!E25*GOOGLEFINANCE(""Currency:KRWEUR""),"""")))))))"),9.35) -> 9.35 | M25: ='Data in Local Currency'!F25 -> 2000 | N25: =IFERROR(__xludf.DUMMYFUNCTION("IF($D25=""Euro"",'Data in Local Currency'!G25, IF($D25=""Dolar"",'Data in Local Currency'!G25*GOOGLEFINANCE(""Currency:USDEUR""), IF($D25=""Franco Suíço"",'Data in Local Currency'!G25*GOOGLEFINANCE(""Currency:CHFEUR""), IF($D25=""Libra Esterlina"", 'Data "&"in Local Currency'!G25*GOOGLEFINANCE(""Currency:GBPEUR""), IF($D25=""Iene"",'Data in Local Currency'!G25*GOOGLEFINANCE(""Currency:JPYEUR""), IF($D25=""HKD"",'Data in Local Currency'!G25*GOOGLEFINANCE(""Currency:HKDEUR""), IF($D25=""KRW"",'Data in Local Cu"&"rrency'!G25*GOOGLEFINANCE(""Currency:KRWEUR""),"""")))))))"),11.0) -> 11 | O25: 10.1 | P25: 0.84 | R25: Sim | S25: 0
A26: SANOFI | B26: SAN FP Equity | C26: FR0000120578 | D26: Euro | E26: 4 | F26: 3.8 | G26: 3.5 | H26: 4.5 | I26: 16 | J26: 77 | K26: 82 | L26: =IFERROR(__xludf.DUMMYFUNCTION("IF($D26=""Euro"",'Data in Local Currency'!E26, IF($D26=""Dolar"",'Data in Local Currency'!E26*GOOGLEFINANCE(""Currency:USDEUR""), IF($D26=""Franco Suíço"",'Data in Local Currency'!E26*GOOGLEFINANCE(""Currency:CHFEUR""), IF($D26=""Libra Esterlina"", 'Data "&"in Local Currency'!E26*GOOGLEFINANCE(""Currency:GBPEUR""), IF($D26=""Iene"",'Data in Local Currency'!E26*GOOGLEFINANCE(""Currency:JPYEUR""), IF($D26=""HKD"",'Data in Local Currency'!E26*GOOGLEFINANCE(""Currency:HKDEUR""), IF($D26=""KRW"",'Data in Local Cu"&"rrency'!E26*GOOGLEFINANCE(""Currency:KRWEUR""),"""")))))))"),7.19) -> 7.19 | M26: ='Data in Local Currency'!F26 -> 2000 | N26: =IFERROR(__xludf.DUMMYFUNCTION("IF($D26=""Euro"",'Data in Local Currency'!G26, IF($D26=""Dolar"",'Data in Local Currency'!G26*GOOGLEFINANCE(""Currency:USDEUR""), IF($D26=""Franco Suíço"",'Data in Local Currency'!G26*GOOGLEFINANCE(""Currency:CHFEUR""), IF($D26=""Libra Esterlina"", 'Data "&"in Local Currency'!G26*GOOGLEFINANCE(""Currency:GBPEUR""), IF($D26=""Iene"",'Data in Local Currency'!G26*GOOGLEFINANCE(""Currency:JPYEUR""), IF($D26=""HKD"",'Data in Local Currency'!G26*GOOGLEFINANCE(""Currency:HKDEUR""), IF($D26=""KRW"",'Data in Local Cu"&"rrency'!G26*GOOGLEFINANCE(""Currency:KRWEUR""),"""")))))))"),86.61) -> 86.61 | O26: 94.04 | P26: 37.76 | Q26: 11.8 | R26: Sim | S26: 4
A27: KONINKLIJKE PHIL | B27: PHIA NA Equity | C27: NL0000009538 | D27: Euro | E27: 4.1 | F27: 4 | G27: 3.6 | H27: 4.1 | I27: 16 | J27: 77 | K27: 70 | L27: =IFERROR(__xludf.DUMMYFUNCTION("IF($D27=""Euro"",'Data in Local Currency'!E27, IF($D27=""Dolar"",'Data in Local Currency'!E27*GOOGLEFINANCE(""Currency:USDEUR""), IF($D27=""Franco Suíço"",'Data in Local Currency'!E27*GOOGLEFINANCE(""Currency:CHFEUR""), IF($D27=""Libra Esterlina"", 'Data "&"in Local Currency'!E27*GOOGLEFINANCE(""Currency:GBPEUR""), IF($D27=""Iene"",'Data in Local Currency'!E27*GOOGLEFINANCE(""Currency:JPYEUR""), IF($D27=""HKD"",'Data in Local Currency'!E27*GOOGLEFINANCE(""Currency:HKDEUR""), IF($D27=""KRW"",'Data in Local Cu"&"rrency'!E27*GOOGLEFINANCE(""Currency:KRWEUR""),"""")))))))"),1.88) -> 1.88 | M27: ='Data in Local Currency'!F27 -> 1995 | N27: =IFERROR(__xludf.DUMMYFUNCTION("IF($D27=""Euro"",'Data in Local Currency'!G27, IF($D27=""Dolar"",'Data in Local Currency'!G27*GOOGLEFINANCE(""Currency:USDEUR""), IF($D27=""Franco Suíço"",'Data in Local Currency'!G27*GOOGLEFINANCE(""Currency:CHFEUR""), IF($D27=""Libra Esterlina"", 'Data "&"in Local Currency'!G27*GOOGLEFINANCE(""Currency:GBPEUR""), IF($D27=""Iene"",'Data in Local Currency'!G27*GOOGLEFINANCE(""Currency:JPYEUR""), IF($D27=""HKD"",'Data in Local Currency'!G27*GOOGLEFINANCE(""Currency:HKDEUR""), IF($D27=""KRW"",'Data in Local Cu"&"rrency'!G27*GOOGLEFINANCE(""Currency:KRWEUR""),"""")))))))"),31.19) -> 31.19 | O27: 28.28 | P27: 17.16 | Q27: 1.85 | R27: Sim | S27: 6
A28: ABRDN PLC | B28: ABDN LN Equity | C28: GB00BF8Q6K64 | D28: Libra Esterlina | E28: 3.3 | F28: 3.1 | G28: 2.7 | H28: N/A | I28: N/A | J28: N/A | K28: N/A | L28: =IFERROR(__xludf.DUMMYFUNCTION("IF($D28=""Euro"",'Data in Local Currency'!E28, IF($D28=""Dolar"",'Data in Local Currency'!E28*GOOGLEFINANCE(""Currency:USDEUR""), IF($D28=""Franco Suíço"",'Data in Local Currency'!E28*GOOGLEFINANCE(""Currency:CHFEUR""), IF($D28=""Libra Esterlina"", 'Data "&"in Local Currency'!E28*GOOGLEFINANCE(""Currency:GBPEUR""), IF($D28=""Iene"",'Data in Local Currency'!E28*GOOGLEFINANCE(""Currency:JPYEUR""), IF($D28=""HKD"",'Data in Local Currency'!E28*GOOGLEFINANCE(""Currency:HKDEUR""), IF($D28=""KRW"",'Data in Local Cu"&"rrency'!E28*GOOGLEFINANCE(""Currency:KRWEUR""),"""")))))))"),441.71072254848) -> 441.71072 | M28: ='Data in Local Currency'!F28 -> 2006 | N28: =IFERROR(__xludf.DUMMYFUNCTION("IF($D28=""Euro"",'Data in Local Currency'!G28, IF($D28=""Dolar"",'Data in Local Currency'!G28*GOOGLEFINANCE(""Currency:USDEUR""), IF($D28=""Franco Suíço"",'Data in Local Currency'!G28*GOOGLEFINANCE(""Currency:CHFEUR""), IF($D28=""Libra Esterlina"", 'Data "&"in Local Currency'!G28*GOOGLEFINANCE(""Currency:GBPEUR""), IF($D28=""Iene"",'Data in Local Currency'!G28*GOOGLEFINANCE(""Currency:JPYEUR""), IF($D28=""HKD"",'Data in Local Currency'!G28*GOOGLEFINANCE(""Currency:HKDEUR""), IF($D28=""KRW"",'Data in Local Cu"&"rrency'!G28*GOOGLEFINANCE(""Currency:KRWEUR""),"""")))))))"),500.06280596876996) -> 500.06281 | O28: 244.36 | P28: 2.15 | R28: Não
A29: ROCHE HLDGGENUS | B29: ROG SW Equity | C29: CH0012032048 | D29: Franco Suíço | E29: 4.3 | F29: 4.2 | G29: 3.7 | H29: 4.5 | I29: 52 | J29: 82 | K29: 73 | L29: =IFERROR(__xludf.DUMMYFUNCTION("IF($D29=""Euro"",'Data in Local Currency'!E29, IF($D29=""Dolar"",'Data in Local Currency'!E29*GOOGLEFINANCE(""Currency:USDEUR""), IF($D29=""Franco Suíço"",'Data in Local Currency'!E29*GOOGLEFINANCE(""Currency:CHFEUR""), IF($D29=""Libra Esterlina"", 'Data "&"in Local Currency'!E29*GOOGLEFINANCE(""Currency:GBPEUR""), IF($D29=""Iene"",'Data in Local Currency'!E29*GOOGLEFINANCE(""Currency:JPYEUR""), IF($D29=""HKD"",'Data in Local Currency'!E29*GOOGLEFINANCE(""Currency:HKDEUR""), IF($D29=""KRW"",'Data in Local Cu"&"rrency'!E29*GOOGLEFINANCE(""Currency:KRWEUR""),"""")))))))"),76.16234342399999) -> 76.162343 | M29: ='Data in Local Currency'!F29 -> 1995 | N29: =IFERROR(__xludf.DUMMYFUNCTION("IF($D29=""Euro"",'Data in Local Currency'!G29, IF($D29=""Dolar"",'Data in Local Currency'!G29*GOOGLEFINANCE(""Currency:USDEUR""), IF($D29=""Franco Suíço"",'Data in Local Currency'!G29*GOOGLEFINANCE(""Currency:CHFEUR""), IF($D29=""Libra Esterlina"", 'Data "&"in Local Currency'!G29*GOOGLEFINANCE(""Currency:GBPEUR""), IF($D29=""Iene"",'Data in Local Currency'!G29*GOOGLEFINANCE(""Currency:JPYEUR""), IF($D29=""HKD"",'Data in Local Currency'!G29*GOOGLEFINANCE(""Currency:HKDEUR""), IF($D29=""KRW"",'Data in Local Cu"&"rrency'!G29*GOOGLEFINANCE(""Currency:KRWEUR""),"""")))))))"),256.27013952) -> 256.27014 | O29: 355.21 | P29: 61.14 | Q29: 21.16 | R29: Sim | S29: 0
A30: ACERINOX | B30: ACX SM Equity | C30: ES0132105018 | D30: Euro | E30: 3.3 | F30: 2.6 | G30: 3 | H30: N/A | I30: N/A | J30: N/A | K30: N/A | L30: =IFERROR(__xludf.DUMMYFUNCTION("IF($D30=""Euro"",'Data in Local Currency'!E30, IF($D30=""Dolar"",'Data in Local Currency'!E30*GOOGLEFINANCE(""Currency:USDEUR""), IF($D30=""Franco Suíço"",'Data in Local Currency'!E30*GOOGLEFINANCE(""Currency:CHFEUR""), IF($D30=""Libra Esterlina"", 'Data "&"in Local Currency'!E30*GOOGLEFINANCE(""Currency:GBPEUR""), IF($D30=""Iene"",'Data in Local Currency'!E30*GOOGLEFINANCE(""Currency:JPYEUR""), IF($D30=""HKD"",'Data in Local Currency'!E30*GOOGLEFINANCE(""Currency:HKDEUR""), IF($D30=""KRW"",'Data in Local Cu"&"rrency'!E30*GOOGLEFINANCE(""Currency:KRWEUR""),"""")))))))"),9.35) -> 9.35 | M30: ='Data in Local Currency'!F30 -> 2000 | N30: =IFERROR(__xludf.DUMMYFUNCTION("IF($D30=""Euro"",'Data in Local Currency'!G30, IF($D30=""Dolar"",'Data in Local Currency'!G30*GOOGLEFINANCE(""Currency:USDEUR""), IF($D30=""Franco Suíço"",'Data in Local Currency'!G30*GOOGLEFINANCE(""Currency:CHFEUR""), IF($D30=""Libra Esterlina"", 'Data "&"in Local Currency'!G30*GOOGLEFINANCE(""Currency:GBPEUR""), IF($D30=""Iene"",'Data in Local Currency'!G30*GOOGLEFINANCE(""Currency:JPYEUR""), IF($D30=""HKD"",'Data in Local Currency'!G30*GOOGLEFINANCE(""Currency:HKDEUR""), IF($D30=""KRW"",'Data in Local Cu"&"rrency'!G30*GOOGLEFINANCE(""Currency:KRWEUR""),"""")))))))"),12.82) -> 12.82 | O30: 10.72 | P30: 6.71 | Q30: 0.99 | R30: Sim | S30: 0
A31: VOPAK | B31: VPK NA Equity | C31: NL0009432491 | D31: Euro | E31: 3.9 | F31: 3.5 | G31: 3.2 | H31: N/A | I31: N/A | J31: N/A | K31: N/A | L31: =IFERROR(__xludf.DUMMYFUNCTION("IF($D31=""Euro"",'Data in Local Currency'!E31, IF($D31=""Dolar"",'Data in Local Currency'!E31*GOOGLEFINANCE(""Currency:USDEUR""), IF($D31=""Franco Suíço"",'Data in Local Currency'!E31*GOOGLEFINANCE(""Currency:CHFEUR""), IF($D31=""Libra Esterlina"", 'Data "&"in Local Currency'!E31*GOOGLEFINANCE(""Currency:GBPEUR""), IF($D31=""Iene"",'Data in Local Currency'!E31*GOOGLEFINANCE(""Currency:JPYEUR""), IF($D31=""HKD"",'Data in Local Currency'!E31*GOOGLEFINANCE(""Currency:HKDEUR""), IF($D31=""KRW"",'Data in Local Cu"&"rrency'!E31*GOOGLEFINANCE(""Currency:KRWEUR""),"""")))))))"),11.8) -> 11.8 | M31: ='Data in Local Currency'!F31 -> 2000 | N31: =IFERROR(__xludf.DUMMYFUNCTION("IF($D31=""Euro"",'Data in Local Currency'!G31, IF($D31=""Dolar"",'Data in Local Currency'!G31*GOOGLEFINANCE(""Currency:USDEUR""), IF($D31=""Franco Suíço"",'Data in Local Currency'!G31*GOOGLEFINANCE(""Currency:CHFEUR""), IF($D31=""Libra Esterlina"", 'Data "&"in Local Currency'!G31*GOOGLEFINANCE(""Currency:GBPEUR""), IF($D31=""Iene"",'Data in Local Currency'!G31*GOOGLEFINANCE(""Currency:JPYEUR""), IF($D31=""HKD"",'Data in Local Currency'!G31*GOOGLEFINANCE(""Currency:HKDEUR""), IF($D31=""KRW"",'Data in Local Cu"&"rrency'!G31*GOOGLEFINANCE(""Currency:KRWEUR""),"""")))))))"),41.42) -> 41.42 | O31: 28.05 | P31: 1.23 | Q31: 0.67 | R31: Não
A32: CBRE GROUP INCA | B32: CBRE US Equity | C32: US12504L1098 | D32: Dolar | E32: 4 | F32: 3.9 | G32: 3.6 | H32: 3.8 | I32: 22 | J32: 80 | K32: 71 | L32: =IFERROR(__xludf.DUMMYFUNCTION("IF($D32=""Euro"",'Data in Local Currency'!E32, IF($D32=""Dolar"",'Data in Local Currency'!E32*GOOGLEFINANCE(""Currency:USDEUR""), IF($D32=""Franco Suíço"",'Data in Local Currency'!E32*GOOGLEFINANCE(""Currency:CHFEUR""), IF($D32=""Libra Esterlina"", 'Data "&"in Local Currency'!E32*GOOGLEFINANCE(""Currency:GBPEUR""), IF($D32=""Iene"",'Data in Local Currency'!E32*GOOGLEFINANCE(""Currency:JPYEUR""), IF($D32=""HKD"",'Data in Local Currency'!E32*GOOGLEFINANCE(""Currency:HKDEUR""), IF($D32=""KRW"",'Data in Local Cu"&"rrency'!E32*GOOGLEFINANCE(""Currency:KRWEUR""),"""")))))))"),5.803938) -> 5.803938 | M32: ='Data in Local Currency'!F32 -> 2004 | N32: =IFERROR(__xludf.DUMMYFUNCTION("IF($D32=""Euro"",'Data in Local Currency'!G32, IF($D32=""Dolar"",'Data in Local Currency'!G32*GOOGLEFINANCE(""Currency:USDEUR""), IF($D32=""Franco Suíço"",'Data in Local Currency'!G32*GOOGLEFINANCE(""Currency:CHFEUR""), IF($D32=""Libra Esterlina"", 'Data "&"in Local Currency'!G32*GOOGLEFINANCE(""Currency:GBPEUR""), IF($D32=""Iene"",'Data in Local Currency'!G32*GOOGLEFINANCE(""Currency:JPYEUR""), IF($D32=""HKD"",'Data in Local Currency'!G32*GOOGLEFINANCE(""Currency:HKDEUR""), IF($D32=""KRW"",'Data in Local Cu"&"rrency'!G32*GOOGLEFINANCE(""Currency:KRWEUR""),"""")))))))"),32.938038) -> 32.938038 | O32: 81.43 | P32: 25.27 | R32: Sim | S32: 2
A33: MEDTRONIC PLC | B33: MDT US Equity | C33: IE00BTN1Y115 | D33: Dolar | E33: 4.1 | F33: 4 | G33: 3.6 | H33: 4.4 | I33: 29 | J33: 82 | K33: 70 | L33: =IFERROR(__xludf.DUMMYFUNCTION("IF($D33=""Euro"",'Data in Local Currency'!E33, IF($D33=""Dolar"",'Data in Local Currency'!E33*GOOGLEFINANCE(""Currency:USDEUR""), IF($D33=""Franco Suíço"",'Data in Local Currency'!E33*GOOGLEFINANCE(""Currency:CHFEUR""), IF($D33=""Libra Esterlina"", 'Data "&"in Local Currency'!E33*GOOGLEFINANCE(""Currency:GBPEUR""), IF($D33=""Iene"",'Data in Local Currency'!E33*GOOGLEFINANCE(""Currency:JPYEUR""), IF($D33=""HKD"",'Data in Local Currency'!E33*GOOGLEFINANCE(""Currency:HKDEUR""), IF($D33=""KRW"",'Data in Local Cu"&"rrency'!E33*GOOGLEFINANCE(""Currency:KRWEUR""),"""")))))))"),0.43230599999999997) -> 0.432306 | M33: ='Data in Local Currency'!F33 -> 1984 | N33: =IFERROR(__xludf.DUMMYFUNCTION("IF($D33=""Euro"",'Data in Local Currency'!G33, IF($D33=""Dolar"",'Data in Local Currency'!G33*GOOGLEFINANCE(""Currency:USDEUR""), IF($D33=""Franco Suíço"",'Data in Local Currency'!G33*GOOGLEFINANCE(""Currency:CHFEUR""), IF($D33=""Libra Esterlina"", 'Data "&"in Local Currency'!G33*GOOGLEFINANCE(""Currency:GBPEUR""), IF($D33=""Iene"",'Data in Local Currency'!G33*GOOGLEFINANCE(""Currency:JPYEUR""), IF($D33=""HKD"",'Data in Local Currency'!G33*GOOGLEFINANCE(""Currency:HKDEUR""), IF($D33=""KRW"",'Data in Local Cu"&"rrency'!G33*GOOGLEFINANCE(""Currency:KRWEUR""),"""")))))))"),76.426182) -> 76.426182 | O33: 98.3 | P33: 27.43 | Q33: 7.5 | R33: Não
A34: ANHEUSERBUSCH I | B34: ABI BB Equity | C34: BE0974293251 | D34: Euro | E34: 3.8 | F34: 3.8 | G34: 3.4 | H34: 3.3 | I34: 34 | J34: 60 | K34: 67 | L34: =IFERROR(__xludf.DUMMYFUNCTION("IF($D34=""Euro"",'Data in Local Currency'!E34, IF($D34=""Dolar"",'Data in Local Currency'!E34*GOOGLEFINANCE(""Currency:USDEUR""), IF($D34=""Franco Suíço"",'Data in Local Currency'!E34*GOOGLEFINANCE(""Currency:CHFEUR""), IF($D34=""Libra Esterlina"", 'Data "&"in Local Currency'!E34*GOOGLEFINANCE(""Currency:GBPEUR""), IF($D34=""Iene"",'Data in Local Currency'!E34*GOOGLEFINANCE(""Currency:JPYEUR""), IF($D34=""HKD"",'Data in Local Currency'!E34*GOOGLEFINANCE(""Currency:HKDEUR""), IF($D34=""KRW"",'Data in Local Cu"&"rrency'!E34*GOOGLEFINANCE(""Currency:KRWEUR""),"""")))))))"),23.21) -> 23.21 | M34: ='Data in Local Currency'!F34 -> 2000 | N34: =IFERROR(__xludf.DUMMYFUNCTION("IF($D34=""Euro"",'Data in Local Currency'!G34, IF($D34=""Dolar"",'Data in Local Currency'!G34*GOOGLEFINANCE(""Currency:USDEUR""), IF($D34=""Franco Suíço"",'Data in Local Currency'!G34*GOOGLEFINANCE(""Currency:CHFEUR""), IF($D34=""Libra Esterlina"", 'Data "&"in Local Currency'!G34*GOOGLEFINANCE(""Currency:GBPEUR""), IF($D34=""Iene"",'Data in Local Currency'!G34*GOOGLEFINANCE(""Currency:JPYEUR""), IF($D34=""HKD"",'Data in Local Currency'!G34*GOOGLEFINANCE(""Currency:HKDEUR""), IF($D34=""KRW"",'Data in Local Cu"&"rrency'!G34*GOOGLEFINANCE(""Currency:KRWEUR""),"""")))))))"),103.4) -> 103.4 | O34: 54.44 | P34: 49.46 | Q34: 17.49 | R34: Não
A35: FANUC CORP | B35: 6954 JP Equity | C35: JP3802400006 | D35: Iene | E35: 3.8 | F35: 3.4 | G35: 3.4 | H35: N/A | I35: N/A | J35: N/A | K35: N/A | L35: =IFERROR(__xludf.DUMMYFUNCTION("IF($D35=""Euro"",'Data in Local Currency'!E35, IF($D35=""Dolar"",'Data in Local Currency'!E35*GOOGLEFINANCE(""Currency:USDEUR""), IF($D35=""Franco Suíço"",'Data in Local Currency'!E35*GOOGLEFINANCE(""Currency:CHFEUR""), IF($D35=""Libra Esterlina"", 'Data "&"in Local Currency'!E35*GOOGLEFINANCE(""Currency:GBPEUR""), IF($D35=""Iene"",'Data in Local Currency'!E35*GOOGLEFINANCE(""Currency:JPYEUR""), IF($D35=""HKD"",'Data in Local Currency'!E35*GOOGLEFINANCE(""Currency:HKDEUR""), IF($D35=""KRW"",'Data in Local Cu"&"rrency'!E35*GOOGLEFINANCE(""Currency:KRWEUR""),"""")))))))"),79.3906188) -> 79.390619 | M35: ='Data in Local Currency'!F35 -> 2000 | N35: =IFERROR(__xludf.DUMMYFUNCTION("IF($D35=""Euro"",'Data in Local Currency'!G35, IF($D35=""Dolar"",'Data in Local Currency'!G35*GOOGLEFINANCE(""Currency:USDEUR""), IF($D35=""Franco Suíço"",'Data in Local Currency'!G35*GOOGLEFINANCE(""Currency:CHFEUR""), IF($D35=""Libra Esterlina"", 'Data "&"in Local Currency'!G35*GOOGLEFINANCE(""Currency:GBPEUR""), IF($D35=""Iene"",'Data in Local Currency'!G35*GOOGLEFINANCE(""Currency:JPYEUR""), IF($D35=""HKD"",'Data in Local Currency'!G35*GOOGLEFINANCE(""Currency:HKDEUR""), IF($D35=""KRW"",'Data in Local Cu"&"rrency'!G35*GOOGLEFINANCE(""Currency:KRWEUR""),"""")))))))"),168.09294102) -> 168.09294 | O35: 156.6 | P35: 4.06 | Q35: 1.16 | R35: Não
A36: EURONAV NV | B36: EURN BB Equity | C36: BE0003816338 | D36: Euro | E36: 4.4 | F36: 4.1 | G36: 3.9 | H36: N/A | I36: N/A | J36: N/A | K36: N/A | L36: =IFERROR(__xludf.DUMMYFUNCTION("IF($D36=""Euro"",'Data in Local Currency'!E36, IF($D36=""Dolar"",'Data in Local Currency'!E36*GOOGLEFINANCE(""Currency:USDEUR""), IF($D36=""Franco Suíço"",'Data in Local Currency'!E36*GOOGLEFINANCE(""Currency:CHFEUR""), IF($D36=""Libra Esterlina"", 'Data "&"in Local Currency'!E36*GOOGLEFINANCE(""Currency:GBPEUR""), IF($D36=""Iene"",'Data in Local Currency'!E36*GOOGLEFINANCE(""Currency:JPYEUR""), IF($D36=""HKD"",'Data in Local Currency'!E36*GOOGLEFINANCE(""Currency:HKDEUR""), IF($D36=""KRW"",'Data in Local Cu"&"rrency'!E36*GOOGLEFINANCE(""Currency:KRWEUR""),"""")))))))"),19.1) -> 19.1 | M36: ='Data in Local Currency'!F36 -> 2004 | N36: =IFERROR(__xludf.DUMMYFUNCTION("IF($D36=""Euro"",'Data in Local Currency'!G36, IF($D36=""Dolar"",'Data in Local Currency'!G36*GOOGLEFINANCE(""Currency:USDEUR""), IF($D36=""Franco Suíço"",'Data in Local Currency'!G36*GOOGLEFINANCE(""Currency:CHFEUR""), IF($D36=""Libra Esterlina"", 'Data "&"in Local Currency'!G36*GOOGLEFINANCE(""Currency:GBPEUR""), IF($D36=""Iene"",'Data in Local Currency'!G36*GOOGLEFINANCE(""Currency:JPYEUR""), IF($D36=""HKD"",'Data in Local Currency'!G36*GOOGLEFINANCE(""Currency:HKDEUR""), IF($D36=""KRW"",'Data in Local Cu"&"rrency'!G36*GOOGLEFINANCE(""Currency:KRWEUR""),"""")))))))"),7.28) -> 7.28 | O36: 9.9 | P36: 0.38 | Q36: 0.04 | R36: Não
A37: ORANGE | B37: ORA FP Equity | C37: FR0000133308 | D37: Euro | E37: 4.1 | F37: 4 | G37: 3.7 | H37: 4.5 | I37: 6 | J37: 81 | K37: 72 | L37: =IFERROR(__xludf.DUMMYFUNCTION("IF($D37=""Euro"",'Data in Local Currency'!E37, IF($D37=""Dolar"",'Data in Local Currency'!E37*GOOGLEFINANCE(""Currency:USDEUR""), IF($D37=""Franco Suíço"",'Data in Local Currency'!E37*GOOGLEFINANCE(""Currency:CHFEUR""), IF($D37=""Libra Esterlina"", 'Data "&"in Local Currency'!E37*GOOGLEFINANCE(""Currency:GBPEUR""), IF($D37=""Iene"",'Data in Local Currency'!E37*GOOGLEFINANCE(""Currency:JPYEUR""), IF($D37=""HKD"",'Data in Local Currency'!E37*GOOGLEFINANCE(""Currency:HKDEUR""), IF($D37=""KRW"",'Data in Local Cu"&"rrency'!E37*GOOGLEFINANCE(""Currency:KRWEUR""),"""")))))))"),167.5) -> 167.5 | M37: ='Data in Local Currency'!F37 -> 2000 | N37: =IFERROR(__xludf.DUMMYFUNCTION("IF($D37=""Euro"",'Data in Local Currency'!G37, IF($D37=""Dolar"",'Data in Local Currency'!G37*GOOGLEFINANCE(""Currency:USDEUR""), IF($D37=""Franco Suíço"",'Data in Local Currency'!G37*GOOGLEFINANCE(""Currency:CHFEUR""), IF($D37=""Libra Esterlina"", 'Data "&"in Local Currency'!G37*GOOGLEFINANCE(""Currency:GBPEUR""), IF($D37=""Iene"",'Data in Local Currency'!G37*GOOGLEFINANCE(""Currency:JPYEUR""), IF($D37=""HKD"",'Data in Local Currency'!G37*GOOGLEFINANCE(""Currency:HKDEUR""), IF($D37=""KRW"",'Data in Local Cu"&"rrency'!G37*GOOGLEFINANCE(""Currency:KRWEUR""),"""")))))))"),14.2) -> 14.2 | O37: 10.69 | P37: 42.52 | Q37: 12.31 | R37: Sim | S37: 6
A38: LAM RESEARCH | B38: LRCX US Equity | C38: US5128071082 | D38: Dolar | E38: 4.2 | F38: 4.2 | G38: 3.8 | H38: 4.2 | I38: 18 | J38: 80 | K38: 65 | L38: =IFERROR(__xludf.DUMMYFUNCTION("IF($D38=""Euro"",'Data in Local Currency'!E38, IF($D38=""Dolar"",'Data in Local Currency'!E38*GOOGLEFINANCE(""Currency:USDEUR""), IF($D38=""Franco Suíço"",'Data in Local Currency'!E38*GOOGLEFINANCE(""Currency:CHFEUR""), IF($D38=""Libra Esterlina"", 'Data "&"in Local Currency'!E38*GOOGLEFINANCE(""Currency:GBPEUR""), IF($D38=""Iene"",'Data in Local Currency'!E38*GOOGLEFINANCE(""Currency:JPYEUR""), IF($D38=""HKD"",'Data in Local Currency'!E38*GOOGLEFINANCE(""Currency:HKDEUR""), IF($D38=""KRW"",'Data in Local Cu"&"rrency'!E38*GOOGLEFINANCE(""Currency:KRWEUR""),"""")))))))"),2.143134) -> 2.143134 | M38: ='Data in Local Currency'!F38 -> 1984 | N38: =IFERROR(__xludf.DUMMYFUNCTION("IF($D38=""Euro"",'Data in Local Currency'!G38, IF($D38=""Dolar"",'Data in Local Currency'!G38*GOOGLEFINANCE(""Currency:USDEUR""), IF($D38=""Franco Suíço"",'Data in Local Currency'!G38*GOOGLEFINANCE(""Currency:CHFEUR""), IF($D38=""Libra Esterlina"", 'Data "&"in Local Currency'!G38*GOOGLEFINANCE(""Currency:GBPEUR""), IF($D38=""Iene"",'Data in Local Currency'!G38*GOOGLEFINANCE(""Currency:JPYEUR""), IF($D38=""HKD"",'Data in Local Currency'!G38*GOOGLEFINANCE(""Currency:HKDEUR""), IF($D38=""KRW"",'Data in Local Cu"&"rrency'!G38*GOOGLEFINANCE(""Currency:KRWEUR""),"""")))))))"),133.23302999999999) -> 133.23303 | O38: 493.22 | P38: 13.32 | Q38: 4.35 | R38: Não
A39: GENERALI ASSIC | B39: G IM Equity | C39: IT0000062072 | D39: Euro | E39: 3.8 | F39: 3.7 | G39: 3.5 | H39: N/A | I39: N/A | J39: N/A | K39: N/A | L39: =IFERROR(__xludf.DUMMYFUNCTION("IF($D39=""Euro"",'Data in Local Currency'!E39, IF($D39=""Dolar"",'Data in Local Currency'!E39*GOOGLEFINANCE(""Currency:USDEUR""), IF($D39=""Franco Suíço"",'Data in Local Currency'!E39*GOOGLEFINANCE(""Currency:CHFEUR""), IF($D39=""Libra Esterlina"", 'Data "&"in Local Currency'!E39*GOOGLEFINANCE(""Currency:GBPEUR""), IF($D39=""Iene"",'Data in Local Currency'!E39*GOOGLEFINANCE(""Currency:JPYEUR""), IF($D39=""HKD"",'Data in Local Currency'!E39*GOOGLEFINANCE(""Currency:HKDEUR""), IF($D39=""KRW"",'Data in Local Cu"&"rrency'!E39*GOOGLEFINANCE(""Currency:KRWEUR""),"""")))))))"),13.56) -> 13.56 | M39: ='Data in Local Currency'!F39 -> 1987 | N39: =IFERROR(__xludf.DUMMYFUNCTION("IF($D39=""Euro"",'Data in Local Currency'!G39, IF($D39=""Dolar"",'Data in Local Currency'!G39*GOOGLEFINANCE(""Currency:USDEUR""), IF($D39=""Franco Suíço"",'Data in Local Currency'!G39*GOOGLEFINANCE(""Currency:CHFEUR""), IF($D39=""Libra Esterlina"", 'Data "&"in Local Currency'!G39*GOOGLEFINANCE(""Currency:GBPEUR""), IF($D39=""Iene"",'Data in Local Currency'!G39*GOOGLEFINANCE(""Currency:JPYEUR""), IF($D39=""HKD"",'Data in Local Currency'!G39*GOOGLEFINANCE(""Currency:HKDEUR""), IF($D39=""KRW"",'Data in Local Cu"&"rrency'!G39*GOOGLEFINANCE(""Currency:KRWEUR""),"""")))))))"),14.53) -> 14.53 | O39: 18.82 | P39: 97.2 | R39: Sim | S39: 0
A40: DEUTSCHE BOERSE | B40: DB1 GY Equity | C40: DE0005810055 | D40: Euro | E40: 4.3 | F40: 4.3 | G40: 4 | H40: N/A | I40: N/A | J40: N/A | K40: N/A | L40: =IFERROR(__xludf.DUMMYFUNCTION("IF($D40=""Euro"",'Data in Local Currency'!E40, IF($D40=""Dolar"",'Data in Local Currency'!E40*GOOGLEFINANCE(""Currency:USDEUR""), IF($D40=""Franco Suíço"",'Data in Local Currency'!E40*GOOGLEFINANCE(""Currency:CHFEUR""), IF($D40=""Libra Esterlina"", 'Data "&"in Local Currency'!E40*GOOGLEFINANCE(""Currency:GBPEUR""), IF($D40=""Iene"",'Data in Local Currency'!E40*GOOGLEFINANCE(""Currency:JPYEUR""), IF($D40=""HKD"",'Data in Local Currency'!E40*GOOGLEFINANCE(""Currency:HKDEUR""), IF($D40=""KRW"",'Data in Local Cu"&"rrency'!E40*GOOGLEFINANCE(""Currency:KRWEUR""),"""")))))))"),31.8) -> 31.8 | M40: ='Data in Local Currency'!F40 -> 2001 | N40: =IFERROR(__xludf.DUMMYFUNCTION("IF($D40=""Euro"",'Data in Local Currency'!G40, IF($D40=""Dolar"",'Data in Local Currency'!G40*GOOGLEFINANCE(""Currency:USDEUR""), IF($D40=""Franco Suíço"",'Data in Local Currency'!G40*GOOGLEFINANCE(""Currency:CHFEUR""), IF($D40=""Libra Esterlina"", 'Data "&"in Local Currency'!G40*GOOGLEFINANCE(""Currency:GBPEUR""), IF($D40=""Iene"",'Data in Local Currency'!G40*GOOGLEFINANCE(""Currency:JPYEUR""), IF($D40=""HKD"",'Data in Local Currency'!G40*GOOGLEFINANCE(""Currency:HKDEUR""), IF($D40=""KRW"",'Data in Local Cu"&"rrency'!G40*GOOGLEFINANCE(""Currency:KRWEUR""),"""")))))))"),89.85) -> 89.85 | O40: 163.65 | P40: 4.63 | Q40: 2.04 | R40: Sim | S40: 1
A41: WABTEC CORP | B41: WAB US Equity | C41: US9297401088 | D41: Dolar | E41: 3.7 | F41: 3.5 | G41: 3.4 | H41: 2.6 | I41: 14 | J41: 61 | K41: 60 | L41: =IFERROR(__xludf.DUMMYFUNCTION("IF($D41=""Euro"",'Data in Local Currency'!E41, IF($D41=""Dolar"",'Data in Local Currency'!E41*GOOGLEFINANCE(""Currency:USDEUR""), IF($D41=""Franco Suíço"",'Data in Local Currency'!E41*GOOGLEFINANCE(""Currency:CHFEUR""), IF($D41=""Libra Esterlina"", 'Data "&"in Local Currency'!E41*GOOGLEFINANCE(""Currency:GBPEUR""), IF($D41=""Iene"",'Data in Local Currency'!E41*GOOGLEFINANCE(""Currency:JPYEUR""), IF($D41=""HKD"",'Data in Local Currency'!E41*GOOGLEFINANCE(""Currency:HKDEUR""), IF($D41=""KRW"",'Data in Local Cu"&"rrency'!E41*GOOGLEFINANCE(""Currency:KRWEUR""),"""")))))))"),8.508149999999999) -> 8.50815 | M41: ='Data in Local Currency'!F41 -> 1995 | N41: =IFERROR(__xludf.DUMMYFUNCTION("IF($D41=""Euro"",'Data in Local Currency'!G41, IF($D41=""Dolar"",'Data in Local Currency'!G41*GOOGLEFINANCE(""Currency:USDEUR""), IF($D41=""Franco Suíço"",'Data in Local Currency'!G41*GOOGLEFINANCE(""Currency:CHFEUR""), IF($D41=""Libra Esterlina"", 'Data "&"in Local Currency'!G41*GOOGLEFINANCE(""Currency:GBPEUR""), IF($D41=""Iene"",'Data in Local Currency'!G41*GOOGLEFINANCE(""Currency:JPYEUR""), IF($D41=""HKD"",'Data in Local Currency'!G41*GOOGLEFINANCE(""Currency:HKDEUR""), IF($D41=""KRW"",'Data in Local Cu"&"rrency'!G41*GOOGLEFINANCE(""Currency:KRWEUR""),"""")))))))"),77.162022) -> 77.162022 | O41: 86.32 | P41: 7.12 | Q41: 1.32 | R41: Não
...

Sheet Página3
A1: Empresa | B1: BLOOOMBERG TICKER | C1: ISiN Code | D1: Moeda Antiga | E1: Geral | F1: Cultura e valores | G1: Alta liderança | H1: Culture Score | I1: eNPS | J1: CEO | K1: Managers | L1: Preço Ação Primeira Abertura [EUR] | M1: Ano do Preço Ação Primeira Abertura | N1: Valor da ação há 5 anos [EUR] | O1: Preço Ação Último Fechamento [EUR] | P1: Receita 2021 [EUR] | Q1: EBTIDA 2021 [EUR] | R1: Faz parte do Pacto? Sim ou Não | S1: Quantos engagements faz parte?
A2: BMW AG | B2: BMW GY Equity | C2: DE0005190003 | D2: Euro | E2: 4.2 | F2: 3.9 | G2: 3.7 | H2: 4.5 | I2: 31 | J2: 78 | K2: 76 | L2: =IFERROR(__xludf.DUMMYFUNCTION("IF($D2=""Euro"",'Data in Local Currency'!E4, IF($D2=""Dolar"",'Data in Local Currency'!E4*GOOGLEFINANCE(""Currency:USDEUR""), IF($D2=""Franco Suíço"",'Data in Local Currency'!E4*GOOGLEFINANCE(""Currency:CHFEUR""), IF($D2=""Libra Esterlina"", 'Data in Loca"&"l Currency'!E4*GOOGLEFINANCE(""Currency:GBPEUR""), IF($D2=""Iene"",'Data in Local Currency'!E4*GOOGLEFINANCE(""Currency:JPYEUR""), IF($D2=""HKD"",'Data in Local Currency'!E4*GOOGLEFINANCE(""Currency:HKDEUR""), IF($D2=""KRW"",'Data in Local Currency'!E4*GO"&"OGLEFINANCE(""Currency:KRWEUR""),"""")))))))"),14.1) -> 14.1 | M2: ='Data in Local Currency'!F4 -> 1996 | N2: =IFERROR(__xludf.DUMMYFUNCTION("IF($D2=""Euro"",'Data in Local Currency'!G4, IF($D2=""Dolar"",'Data in Local Currency'!G4*GOOGLEFINANCE(""Currency:USDEUR""), IF($D2=""Franco Suíço"",'Data in Local Currency'!G4*GOOGLEFINANCE(""Currency:CHFEUR""), IF($D2=""Libra Esterlina"", 'Data in Loca"&"l Currency'!G4*GOOGLEFINANCE(""Currency:GBPEUR""), IF($D2=""Iene"",'Data in Local Currency'!G4*GOOGLEFINANCE(""Currency:JPYEUR""), IF($D2=""HKD"",'Data in Local Currency'!G4*GOOGLEFINANCE(""Currency:HKDEUR""), IF($D2=""KRW"",'Data in Local Currency'!G4*GO"&"OGLEFINANCE(""Currency:KRWEUR""),"""")))))))"),7.9) -> 7.9 | O2: 76.67 | P2: 111.24 | Q2: 19.94 | R2: Sim | S2: 3
